Workbook

Sheet 🎛 ДАШБОРД CEO
A1: GIS-POINT · ДАШБОРД КЕРІВНИКА
A2: Одна сторінка по воронці Lead Gen→Sales→Delivery→Finance→People. ФАКТ/СТАТУС тягнуться з листів ролей автоматично. ✅ норма · ⚠️ відхилення · ❌ критично.
A4: ВОРОНКА / БЛОК | B4: КЛЮЧОВА МЕТРИКА | C4: ВІДДІЛ | D4: ПЛАН | E4: ФАКТ (авто) | F4: СТАТУС | G4: ТАКТ
A5: Lead Gen | B5: Кваліфіковані зустрічі / SQL | C5: Team Lead LM | E5: =IF('Team Lead LM'!G8="","",'Team Lead LM'!G8) | F5: =IF('Team Lead LM'!H8="","",'Team Lead LM'!H8) | G5: W
A6: Sales | B6: Revenue closed / closing | C6: Sales | E6: =IF('Sales'!G16="","",'Sales'!G16) | F6: =IF('Sales'!H16="","",'Sales'!H16) | G6: W
A7: Sales | B7: Утримання / NRR | C7: Sales | E7: =IF('Sales'!G24="","",'Sales'!G24) | F7: =IF('Sales'!H24="","",'Sales'!H24) | G7: M
A8: Delivery | B8: Проекти здані в строк | C8: Head of Delivery | D8: =IF('Head of Delivery'!G9="","",'Head of Delivery'!G9) | E8: =IF('Head of Delivery'!H9="","",'Head of Delivery'!H9) | F8: =IF('Head of Delivery'!I9="","",'Head of Delivery'!I9) | G8: W
A9: Delivery | B9: Utilization команди | C9: Head of Delivery | D9: =IF('Head of Delivery'!G15="","",'Head of Delivery'!G15) | E9: =IF('Head of Delivery'!H15="","",'Head of Delivery'!H15) | F9: =IF('Head of Delivery'!I15="","",'Head of Delivery'!I15) | G9: W
A10: Delivery | B10: Маржа проектів | C10: Head of Delivery | D10: =IF('Head of Delivery'!G29="","",'Head of Delivery'!G29) | E10: =IF('Head of Delivery'!H29="","",'Head of Delivery'!H29) | F10: =IF('Head of Delivery'!I29="","",'Head of Delivery'!I29) | G10: M
A11: Tech | B11: Sprint delivery rate | C11: CTO | D11: =IF('CTO'!G10="","",'CTO'!G10) | E11: =IF('CTO'!H10="","",'CTO'!H10) | F11: =IF('CTO'!I10="","",'CTO'!I10) | G11: W
A12: Client | B12: Client CSAT | C12: PM | D12: =IF('PM'!G13="","",'PM'!G13) | E12: =IF('PM'!H13="","",'PM'!H13) | F12: =IF('PM'!I13="","",'PM'!I13) | G12: M
A13: Finance | B13: Прострочена дебіторка | C13: Operations | D13: =IF('Operations'!G7="","",'Operations'!G7) | E13: =IF('Operations'!H7="","",'Operations'!H7) | F13: =IF('Operations'!I7="","",'Operations'!I7) | G13: W
A14: Finance | B14: Revenue план/факт (компанія) | C14: CEO | D14: =IF('CEO'!J19="","",'CEO'!J19) | E14: =IF('CEO'!K19="","",'CEO'!K19) | F14: =IF('CEO'!G19="","",'CEO'!G19) | G14: M
A15: People | B15: NPS команди | C15: CEO | D15: =IF('CEO'!J16="","",'CEO'!J16) | E15: =IF('CEO'!K16="","",'CEO'!K16) | F15: =IF('CEO'!G16="","",'CEO'!G16) | G15: Q
A16: Marketing | B16: Inbound leads | C16: Marketing | D16: =IF('Marketing'!G10="","",'Marketing'!G10) | E16: =IF('Marketing'!H10="","",'Marketing'!H10) | F16: =IF('Marketing'!I10="","",'Marketing'!I10) | G16: W

Sheet ⏱ ТАКТ ЗОН
A1: GIS-POINT · ТАКТ ЗОН + ПИТАННЯ ДО НАРАД (v2.1)
A2: Кожна зона привʼязана до наради (такт), де її звіряють, + готове питання. W=тижнева · M=місячна · Q=квартальна. Принцип: у нормі — не обговорюємо, лише відхилення/критичне.
A4: РОЛЬ / ЛИСТ | B4: Z# | C4: БЛОК (Гарніш) | D4: ЗОНА ВІДПОВІДАЛЬНОСТІ | E4: KPI / МЕТРИКА | F4: ТАКТ | G4: НА ЯКІЙ НАРАДІ | H4: ПИТАННЯ НА НАРАДІ
A5: CEO | B5: Z01 | C5: Стратегія | D5: Стратегія і вихід на ринки | E5: % OKR завершено / квартал | F5: Q | G5: Квартальна | H5: Стратегія і вихід на ринки: чи «% OKR завершено / квартал» в нормі? Якщо ні — причина + план дії, власник, дедлайн.
A6: CEO | B6: Z02 | C6: Стратегія | D6: Ключові продажі і партнерства | E6: Нові стратег. контракти / партнерства за квартал | F6: M | G6: Місячна | H6: Ключові продажі і партнерства: чи «Нові стратег. контракти / партнерства за квартал» в нормі? Якщо ні — причина + план дії, власник, дедлайн.
A7: CEO | B7: Z03 | C7: Стратегія | D7: Позиціонування і бренд | E7: Brand visibility (конференції, публікації) / квартал | F7: Q | G7: Квартальна | H7: Позиціонування і бренд: чи «Brand visibility (конференції, публікації) / квартал» в нормі? Якщо ні — причина + план дії, власник, дедлайн.
A8: CEO | B8: Z04 | C8: Люди | D8: Команда і культура | E8: NPS команди | F8: Q | G8: Квартальна | H8: Команда і культура: чи «NPS команди» в нормі? Якщо ні — причина + план дії, власник, дедлайн.
A9: CEO | B9: Z05 | C9: Гроші | D9: Фінансовий результат | E9: Revenue план/факт | F9: M | G9: Місячна | H9: Фінансовий результат: чи «Revenue план/факт» в нормі? Якщо ні — причина + план дії, власник, дедлайн.
A10: CEO | B10: Z06 | C10: Стратегія | D10: Запуск нових напрямків | E10: Нових напрямків запущено / рік | F10: Q | G10: Квартальна | H10: Запуск нових напрямків: чи «Нових напрямків запущено / рік» в нормі? Якщо ні — причина + план дії, власник, дедлайн.
A11: CTO | B11: Z01 | C11: Реалізація | D11: Архітектура і технічні стандарти | E11: Tech debt incidents / місяць | F11: M | G11: Місячна | H11: Архітектура і технічні стандарти: чи «Tech debt incidents / місяць» в нормі? Якщо ні — причина + план дії, власник, дедлайн.
A12: CTO | B12: Z02 | C12: Реалізація | D12: GIS Software Development | E12: Sprint delivery rate (задачі в строк) | F12: W | G12: Тижнева (1-на-1 / групова) | H12: GIS Software Development: чи «Sprint delivery rate (задачі в строк)» в нормі? Якщо ні — причина + план дії, власник, дедлайн.
A13: CTO | B13: Z03 | C13: Стратегія | D13: R&D і нові технології | E13: POC завершено в строк | F13: Q | G13: Квартальна | H13: R&D і нові технології: чи «POC завершено в строк» в нормі? Якщо ні — причина + план дії, власник, дедлайн.
A14: CTO | B14: Z04 | C14: Люди | D14: Управління IT-командою | E14: Developer satisfaction (internal NPS) | F14: Q | G14: Квартальна | H14: Управління IT-командою: чи «Developer satisfaction (internal NPS)» в нормі? Якщо ні — причина + план дії, власник, дедлайн.
A15: CTO | B15: Z05 | C15: Реалізація | D15: Технічна підтримка продажів | E15: Оцінки надано в строк | F15: W | G15: Тижнева (1-на-1 / групова) | H15: Технічна підтримка продажів: чи «Оцінки надано в строк» в нормі? Якщо ні — причина + план дії, власник, дедлайн.
... A63: Marketing | B63: Z04 | C63: Реалізація | D63: Підтримка Sales матеріалами | E63: Sales collateral оновлено за запитом Sales ≤5 днів | F63: M | G63: Місячна | H63: Підтримка Sales матеріалами: чи «Sales collateral оновлено за запитом Sales ≤5 днів» в нормі? Якщо ні — причина + план дії, власник, дедлайн.

Sheet ❓ ПИТАННЯ ДО НАРАД
A1: GIS-POINT · ПИТАННЯ ДО КОЖНОЇ НАРАДИ (v2.3, узгоджено з «Структура нарад v4»)
A2: Скрізь: Пункт 0 (огляд рішень минулої) на старті + 60-сек перевірка в кінці. У нормі не озвучуємо — лише відхилення/❌.
A4: 🟦 ЩОТИЖНЕВА (60–75 хв)
A5: 0. Пункт 0 | B5: Рішення минулого тижня закриті? Прострочене — причина + нова дата (Журнал).
A6: 1. Блокери | B6: Є блокер? Так/Ні. Якщо так — суть + рішення/дедлайн від CEO.
A7: 2. Sales | B7: Пресейли факт/план (MQL|SQL) · запити на оцінку (накопич.) · signed agreements · топ-3 deals: стадія→крок→дата · що треба від CEO · опер. задачі тижня.
A8: 3. TL LeadGen | B8: Meetings booked факт/план · reply/bounce · A/B статус · якість лідів ≥4/5 · ідея автоматизації (парні тижні) · опер. задачі.
A9: 4. Head of Delivery | B9: Проекти 🟢🟡🔴 · де маржа нижче плану · utilization · пресейл-оцінки в строк · опер. задачі.
A10: 5. CTO | B10: Sprint delivery rate · tech blockers · R&D/POC · опер. задачі.
A11: 6. Finance | B11: Cash flow · прострочена дебіторка · рахунки до оплати · опер. задачі.
A12: 8. Фіксація | B12: Хто/що/до коли → Журнал. 60-сек перевірка.
A14: 🟧 МІСЯЧНА (2 год)
A15: 0. Пункт 0 | B15: Минуле вузьке місце розв'язане? Місячні рішення закриті?
A16: 1. Дашборд CEO | B16: Revenue план/факт · Маржа · Utilization · NPS — де ❌ детально (лист 🎛 ДАШБОРД CEO).
A17: 2. Sales | B17: Пресейли/ТЗ/пропозиції/Revenue closed факт/план · Win rate · Win-Loss топ-3 · Thinking Report.
A18: 3. TL LeadGen | B18: Meetings booked (команда+на менеджера) · reply/bounce · якість ≥4/5 · A/B вердикт · автоматизація · Thinking Report.
A19: 4. Head of Delivery | B19: Проекти в строк факт/план · маржа портфелю · revisions · capacity наст. міс · кейси маркетингу · Thinking Report.
A20: 5. CTO | B20: Sprint delivery · POC/R&D · tech debt · кейси · ревю вузьких місць по блоках.
A21: 6. Marketing | B21: Кейси GIS/IT · публікації факт/план · inbound/SEO/LinkedIn · конференції/PR.
A22: 7. Finance+Ops | B22: P&L місяця · cash flow 2 міс · дебіторка · ЗП вчасно · Thinking Report.
A23: 9. Фокус | B23: Вузьке місце місяця → рішення/власник/дедлайн · топ-1 ціль кожного · CEO: 1–3 пріоритети.
A24: Thinking Report | B24: 1) Що дізнались про клієнтів/ринок? 2) Яке джерело спрацювало краще? 3) Що тестували нового? 4) Де втрата грошей/можливості? 5) Що масштабувати?
A26: 🟩 КВАРТАЛЬНА (3–4 год)
A27: 0. OKR підсумок | B27: % виконання Rocks/OKR; що переноситься. Критичне число досягнуте?
A28: Фінрезультат | B28: Revenue план/факт · маржа · cash flow · vs попередній квартал.
A29: По юнітах | B29: Delivery/CTO/Sales/TL/Marketing — факт vs план за квартал + системні проблеми відділу.
A30: Автоматизація | B30: Топ-3 ідеї кожен → CTO: беремо/відкладаємо/відхиляємо; що впровадили — ефект.
A31: Системні проблеми | B31: Топ-3 патерни компанії → рішення + відповідальний.
A32: OKR + ресурси | B32: CEO: пріоритети; кожен: 3 цілі відділу; найм/делегування; перегляд норм матриці (@200).
A33: NPS пульс | B33: Анонімно за тиждень до. NPS<7 → 1-на-1 з керівниками за 5 днів.
A35: ⬜ ПІВРІЧНА / РІЧНА
A36: Люди | B36: A/B/C по командах; ключові наймання; розвиток/заміни.
A37: Стратегія | B37: Велика ціль 2030; ринок; позиціонування; нові напрямки go/no-go.
A38: Гроші | B38: Ре-прогноз бюджету; економіка GIS vs IT; інвестиції.

Sheet ➕ НОВІ ЗОНИ
A1: GIS-POINT · РЕКОМЕНДОВАНІ НОВІ ЗОНИ (до перенесення у листи ролей)
A2: Знайдені прогалини відносно методології Гарніша (блок «Гроші») і нового ритму управління. Перенеси у відповідний лист ролі як нову Z-зону. ★ = критично, ☆ = бажано.
A4: ПРІОР. | B4: РОЛЬ (лист) | C4: ПРОПОНОВАНА ЗОНА | D4: ЩО ВХОДИТЬ | E4: KPI / МЕТРИКА | F4: ПЛАН (норма) | G4: ТАКТ | H4: БЛОК | I4: ЧОМУ ПОТРІБНО
A5: ★ | B5: CEO | C5: Операційний ритм і виконавська дисципліна | D5: • Веде ритм нарад і Журнал рішень • Слідкує, що рішення закриваються • Прибирає зустрічі-для-галочки | E5: % рішень закрито вчасно | F5: ≥80% | G5: M/Q | H5: Реалізація | I5: Зараз ніхто формально не власник самого ритму. Без цього система нарад сповзає у формальність.
A6: ★ | B6: Operations | C6: Грошовий потік і ліквідність | D6: • Прогноз руху коштів на 8–13 тижнів • Контроль касового розриву • Runway | E6: Запас ліквідності (runway), міс / прогноз касового розриву | F6: ≥3 міс | G6: M | H6: Гроші | I6: У матриці є P&L і маржа, але немає cash-flow/runway — ключове в Гарніша (блок «Гроші») і при масштабуванні.
A7: ★ | B7: Operations | C7: Рекрутинг і найм | D7: • Закриття вакансій • Якість найму (A-гравці на випробувальному) • Пайплайн кандидатів | E7: Час закриття вакансії, дн / % проходження випробувального | F7: ≤30 дн / ≥80% | G7: M | H7: Люди | I7: HR-зона покриває лише онбординг. При рості 50→100 найм — окремий критичний процес.
A8: ☆ | B8: CTO | C8: Інформаційна безпека і доступи | D8: • Управління доступами • Бекапи й відновлення • Інциденти безпеки | E8: Інциденти безпеки / квартал · uptime ключових сервісів | F8: 0 критичних · ≥99% | G8: M/Q | H8: Реалізація | I8: Не покрито жодною зоною; критично для роботи з геоданими і на міжнародних ринках.
A9: ☆ | B9: Marketing | C9: Веб-сайт, SEO та аналітика | D9: • Технічне SEO і позиції • Веб-аналітика і конверсії • Швидкість/UX сайту | E9: Органічний трафік / міс · конверсія сайту | F9: зростання MoM | G9: M | H9: Реалізація | I9: Inbound є, але власника сайту/SEO як окремої зони немає — джерело лідів без відповідального.
A10: ★ | B10: Усі ролі | C10: Постійне вдосконалення / автоматизація | D10: • 1 ідея автоматизації /2 тижні • Формат: ручна дія→час→рішення • CTO оцінює пріоритет | E10: Ідей впроваджено / квартал | F10: ≥1 на роль | G10: W/Q | H10: Реалізація | I10: Є в аджені нарад, але не як зона відповідальності — щоб не загубилось.
A11: ☆ | B11: Sales / Delivery / Finance | C11: Навчання ринку (Thinking Report) | D11: • 5 питань про клієнтів/ринок/втрати щомісяця • Інсайт у дію | E11: Інсайтів у дію / місяць | F11: ≥1 | G11: M | H11: Стратегія | I11: Формалізує місячний Thinking Report як відповідальність, а не разову вправу.

Sheet 📊 MONTHLY (авто)
A1: GIS-POINT · ЩОМІСЯЧНИЙ ДАШБОРД (авто) — тягне M-зони з листів ролей
A2: НЕ заповнювати тут. ФАКТ і СТАТУС підтягуються автоматично, коли керівник заповнює свій лист. ✅ норма · ⚠️ відхилення · ❌ критично.
A4: ВІДДІЛ / РОЛЬ | B4: Z# | C4: ЗОНА / МЕТРИКА (з листа ролі) | D4: ПЛАН | E4: ФАКТ (авто) | F4: СТАТУС (авто)
A5: ▌ ЛЮДИ
A6: Head of Delivery | B6: Z05 | C6: =IF('Head of Delivery'!F22="","",'Head of Delivery'!F22) | D6: =IF('Head of Delivery'!G22="","",'Head of Delivery'!G22) | E6: =IF('Head of Delivery'!H22="","",'Head of Delivery'!H22) | F6: =IF('Head of Delivery'!I22="","",'Head of Delivery'!I22)
A7: Operations | B7: Z04 | C7: =IF('Operations'!F16="","",'Operations'!F16) | D7: =IF('Operations'!G16="","",'Operations'!G16) | E7: =IF('Operations'!H16="","",'Operations'!H16) | F7: =IF('Operations'!I16="","",'Operations'!I16)
A8: Team Lead LM | B8: Z02 | C8: =IF('Team Lead LM'!F13="","",'Team Lead LM'!F13) | E8: =IF('Team Lead LM'!G13="","",'Team Lead LM'!G13) | F8: =IF('Team Lead LM'!H13="","",'Team Lead LM'!H13)
A9: ▌ СТРАТЕГІЯ
A10: CEO | B10: Z02 | C10: =IF('CEO'!F10="","",'CEO'!F10) | D10: =IF('CEO'!J10="","",'CEO'!J10) | E10: =IF('CEO'!K10="","",'CEO'!K10) | F10: =IF('CEO'!G10="","",'CEO'!G10)
A11: Marketing | B11: Z01 | C11: =IF('Marketing'!F7="","",'Marketing'!F7) | D11: =IF('Marketing'!G7="","",'Marketing'!G7) | E11: =IF('Marketing'!H7="","",'Marketing'!H7) | F11: =IF('Marketing'!I7="","",'Marketing'!I7)
A12: ▌ РЕАЛІЗАЦІЯ
A13: CTO | B13: Z01 | C13: =IF('CTO'!F7="","",'CTO'!F7) | D13: =IF('CTO'!G7="","",'CTO'!G7) | E13: =IF('CTO'!H7="","",'CTO'!H7) | F13: =IF('CTO'!I7="","",'CTO'!I7)
A14: Operations | B14: Z05 | C14: =IF('Operations'!F19="","",'Operations'!F19) | D14: =IF('Operations'!G19="","",'Operations'!G19) | E14: =IF('Operations'!H19="","",'Operations'!H19) | F14: =IF('Operations'!I19="","",'Operations'!I19)
A15: PM | B15: Z03 | C15: =IF('PM'!F13="","",'PM'!F13) | D15: =IF('PM'!G13="","",'PM'!G13) | E15: =IF('PM'!H13="","",'PM'!H13) | F15: =IF('PM'!I13="","",'PM'!I13)
A16: PM | B16: Z05 | C16: =IF('PM'!F18="","",'PM'!F18) | D16: =IF('PM'!G18="","",'PM'!G18) | E16: =IF('PM'!H18="","",'PM'!H18) | F16: =IF('PM'!I18="","",'PM'!I18)
A17: Sales | B17: Z06 | C17: =IF('Sales'!F28="","",'Sales'!F28) | E17: =IF('Sales'!G28="","",'Sales'!G28) | F17: =IF('Sales'!H28="","",'Sales'!H28)
A18: Sales | B18: Z07 | C18: =IF('Sales'!F32="","",'Sales'!F32) | E18: =IF('Sales'!G32="","",'Sales'!G32) | F18: =IF('Sales'!H32="","",'Sales'!H32)
A19: Team Lead LM | B19: Z06 | C19: =IF('Team Lead LM'!F30="","",'Team Lead LM'!F30) | E19: =IF('Team Lead LM'!G30="","",'Team Lead LM'!G30) | F19: =IF('Team Lead LM'!H30="","",'Team Lead LM'!H30)
A20: Marketing | B20: Z04 | C20: =IF('Marketing'!F16="","",'Marketing'!F16) | D20: =IF('Marketing'!G16="","",'Marketing'!G16) | E20: =IF('Marketing'!H16="","",'Marketing'!H16) | F20: =IF('Marketing'!I16="","",'Marketing'!I16)
A21: ▌ ГРОШІ
A22: CEO | B22: Z05 | C22: =IF('CEO'!F19="","",'CEO'!F19) | D22: =IF('CEO'!J19="","",'CEO'!J19) | E22: =IF('CEO'!K19="","",'CEO'!K19) | F22: =IF('CEO'!G19="","",'CEO'!G19)
A23: Head of Delivery | B23: Z06 | C23: =IF('Head of Delivery'!F26="","",'Head of Delivery'!F26) | D23: =IF('Head of Delivery'!G26="","",'Head of Delivery'!G26) | E23: =IF('Head of Delivery'!H26="","",'Head of Delivery'!H26) | F23: =IF('Head of Delivery'!I26="","",'Head of Delivery'!I26)
A24: Head of Delivery | B24: Z07 | C24: =IF('Head of Delivery'!F29="","",'Head of Delivery'!F29) | D24: =IF('Head of Delivery'!G29="","",'Head of Delivery'!G29) | E24: =IF('Head of Delivery'!H29="","",'Head of Delivery'!H29) | F24: =IF('Head of Delivery'!I29="","",'Head of Delivery'!I29)
A25: Operations | B25: Z02 | C25: =IF('Operations'!F10="","",'Operations'!F10) | D25: =IF('Operations'!G10="","",'Operations'!G10) | E25: =IF('Operations'!H10="","",'Operations'!H10) | F25: =IF('Operations'!I10="","",'Operations'!I10)
A26: Operations | B26: Z03 | C26: =IF('Operations'!F13="","",'Operations'!F13) | D26: =IF('Operations'!G13="","",'Operations'!G13) | E26: =IF('Operations'!H13="","",'Operations'!H13) | F26: =IF('Operations'!I13="","",'Operations'!I13)
A27: Operations | B27: Z06 | C27: =IF('Operations'!F22="","",'Operations'!F22) | D27: =IF('Operations'!G22="","",'Operations'!G22) | E27: =IF('Operations'!H22="","",'Operations'!H22) | F27: =IF('Operations'!I22="","",'Operations'!I22)
A28: PM | B28: Z04 | C28: =IF('PM'!F15="","",'PM'!F15) | D28: =IF('PM'!G15="","",'PM'!G15) | E28: =IF('PM'!H15="","",'PM'!H15) | F28: =IF('PM'!I15="","",'PM'!I15)
A29: Sales | B29: Z05 | C29: =IF('Sales'!F24="","",'Sales'!F24) | E29: =IF('Sales'!G24="","",'Sales'!G24) | F29: =IF('Sales'!H24="","",'Sales'!H24)

Sheet 🏠 Навігація
A2: GIS-POINT · КАРТА ЗОН ВІДПОВІДАЛЬНОСТІ · v3.0
A3: Методологія: Верн Гарніш «Масштабування бізнесу» · Блоки: Люди · Стратегія · Реалізація · Гроші
A4: Операційна модель: Lead Gen → TL LeadGen → Sales → PM → Delivery → Finance
A5: Призначення: Онбординг нових співробітників + Щомісячний мітинг контролю + Дорожня карта масштабування
A7: 👥 Поточна команда (~40 осіб): CEO · CTO + 5 dev · GIS Delivery 22 спец. · 1 PM · Sales Manager + TL LeadGen + 3 Lead Gen Managers · 1 Marketing · Ops/Finance | E7: 🚀 Ціль масштабування — 200 осіб: Green column у кожному листі показує як зміниться роль
B8: ВІДДІЛ / РОЛЬ | C8: БЛОКИ ГАРНІША | D8: ЛИСТ | E8: РОЛЬ У МОДЕЛІ | F8: ЗАРАЗ (≈40 осіб) | G8: ЦІЛЬ
B9: 👔 CEO / Founder | C9: Люди · Стратегія · Гроші | D9: CEO | E9: Стратегія, партнерства, ключові продажі, P&L | F9: 1 особа | G9: CEO → При зростанні компанії з'являються керівники напрямків (продажі, технології, delivery, фінанси). CEO переходить з операційного управління на стратегію, партнерства і розвиток бізнесу.
B10: 💻 CTO / Technology Dept | C10: Реалізація · Стратегія · Люди | D10: CTO | E10: GIS software, web/mobile, R&D, AI/automation | F10: CTO + PM + developers | G10: CTO → З ростом команди розробників з'являються тімліди або Engineering Managers під CTO. CTO перестає управляти людьми напряму і фокусується на архітектурі, технічній стратегії і R&D.
B11: 🗺️ GIS Delivery Dept | C11: Реалізація · Люди | D11: Head of Delivery | E11: LiDAR, CAD/BIM, spatial analysis, UAV processing | F11: Head + PM + RnD + GIS specialists | G11: Head of Delivery → Відділ ділиться на напрямки (LiDAR, CAD/BIM, Аналіз і картографія) — кожен зі своїм тімлідом. Head управляє керівниками напрямків, а не кожним спеціалістом особисто.
B12: 🗺️ Head of GIS Delivery | C12: Реалізація · Гроші | D12: Head of Delivery | E12: Стратегія відділу · PM всіх проектів · Команда (GIS/BIM/Cartography) · Якість · Маржа · Клієнт | F12: 1 Head of GIS Delivery | G12: PM → З'являються окремі PM під кожен напрямок (GIS, BIM, великі enterprise-клієнти). Формується єдиний стандарт управління проектами для всіх.
B13: 🤝 Sales & Business Dev | C13: Реалізація · Гроші | D13: Sales | E13: Leads, discovery, proposals, closing, CRM | F13: Sales Mgr + Team LLgM + LgM | G13: Sales Manager → Sales ділиться на ролі: той хто керує командою, ті хто закривають угоди по вертикалях, і окрема людина що відповідає за CRM і аналітику воронки.
B14: 📣 Marketing | C14: Стратегія · Реалізація | D14: Marketing | E14: Brand, content, SEO, PR, конференції, Sales enablement | F14: 1 Marketer | G14: Marketing → З одного маркетолога-дженераліста виростає команда з чіткою спеціалізацією: контент, дизайн, SEO, PR, зростання. З'являється керівник маркетингу.
B15: ⚙️ Operations & Finance | C15: Гроші · Люди · Реалізація | D15: Operations | E15: P&L, ЗП, інвойси, HR, контракти, бухгалтерія | F15: Finance + Admin + аутсорс-бух | G15: Operations / Finance → Розділяється на три окремі функції: фінанси, HR і юридичний напрямок — кожен зі своїм відповідальним. Критично для роботи на міжнародних ринках.
B16: 🎯 Team Lead LeadGen | C16: Реалізація · Люди | D16: Team Lead LM | E16: Outbound команда, кампанії, сіквенси, якість лідів ≥4/5 | F16: TL + LgM | G16: Team Lead LeadGen → Лідогенерація виростає в окремий підрозділ. TL стає Head of Lead Generation з кількома тімлідами під собою.
B17: 📞 Lead Gen Manager | C17: Реалізація | D17: Lead gen. manager | E17: Outreach LinkedIn+Email → зустрічі з релевантними лідами | F17: 3 менеджери (→4-5) | G17: Lead Gen Manager → Команда зростає і спеціалізується: хтось по email, хтось по LinkedIn, хтось по івентах або конкретних вертикалях. Ти можеш вирости в тімліда свого напрямку.
A18: 📊 Щомісячний огляд
A20: ЯК КОРИСТУВАТИСЯ ФАЙЛОМ
B21: 🔵 ОНБОРДИНГ | C21: Відкрий свій лист. Прочитай всі зони — це твій повний список обов'язків. Зрозумій ПЛАН. Колонка 'ПРИ МАСШТАБІ 200' — як твоя роль зміниться у майбутньому. Онбординг-блок внизу кожного листа пояснює операційну модель.
B22: 🟡 ЩОМІСЯЧНИЙ МІТИНГ (до 5-го числа) | C22: Кожен керівник відділу: 1) заповнює ФАКТ у жовтих клітинках. 2) Ставить СТАТУС (✅ / ⚠️ / ❌). 3) При ⚠️/❌ — коментар з причиною і планом дії. 4) CEO зводить підсумки у лист Monthly.
B23: 🟢 ЩОКВАРТАЛЬНИЙ ПЕРЕГЛЯД | C23: Переглядайте ПЛАН по кожній зоні — чи відповідає він поточному розміру компанії? Оновлюйте колонку масштабу: що вже варто делегувати? Додавайте нові зони при зміні ролей.
B24: 🔴 ЕСКАЛАЦІЯ | C24: ❌ більше 2 місяців підряд → ескалація одразу (не чекати мітингу). ⚠️ → план дій у коментарі протягом 24 год. Sales → PM → Delivery → Finance: кожна проблема вирішується на найнижчому можливому рівні.

Sheet CEO
A2: GIS-POINT · CEO / FOUNDER
A3: Блоки Гарніша: Люди · Стратегія · Гроші | Онбординг + Щомісячний контроль | Модель: Sales → PM → Delivery → Finance
B5: 👥 Команда зараз (≈40 осіб): CEO / Founder — 1 особа | F5: 🚀 При масштабі 200 осіб: CEO + VP-рівень (Sales Dir, Engineering Dir, GIS Dir, CFO) | G5: Місяць огляду: March 2026 | ✏️ Заповни ФАКТ → СТАТУС → КОМЕНТАР при ⚠️/❌
B6: БЛОК (ГАРНІШ) | C6: Z# | D6: ЗОНА ВІДПОВІДАЛЬНОСТІ | E6: КОНКРЕТНІ ОБОВ'ЯЗКИ | F6: KPI / МЕТРИКА | G6: СТАТУС ✅⚠️❌ | H6: КОМЕНТАР / ДІЯ | I6: ПРИ МАСШТАБІ 👥 (що зміниться) | J6: ПЛАН (норма) | K6: ФАКТ (місяць)
B7: Стратегія | C7: Z01 | D7: Стратегія і вихід на ринки | E7: • Визначення стратегічних напрямків: UK, USA, Canada, Germany, Q4Middle East 2026 | F7: % OKR завершено / квартал | G7: — | I7: Делегування стратегічних блоків VP-рівню. CEO — лише top-level OKR. | J7: ≥80 %
E8: • Вибір індустрій і продуктових вертикалей (AgriTech, Fiber, Energy…)
E9: • OKR компанії на квартал і рік
B10: Стратегія | C10: Z02 | D10: Ключові продажі і партнерства | E10: • Стратегічні продажі — контракти >$30K IT | F10: Нові стратег. контракти / партнерства за квартал | G10: — | I10: Sales Director бере ключові продажі. CEO — лише enterprise і стратег. партнери. | J10: ≥1 шт
E11: • Підписання міжнародних партнерств (referral, co-sell, integration)
E12: • Участь у конференціях як обличчя компанії
B13: Стратегія | C13: Z03 | D13: Позиціонування і бренд | E13: • Визначення позиціонування GIS-Point на міжнародному ринку | F13: Brand visibility (конференції, публікації) / квартал | G13: — | I13: CMO бере маркетинг і бренд. CEO — лише стратегічне позиціонування. | J13: ≥3 появи
E14: • Формування value proposition для кожної індустрії
E15: • Публічні виступи, кейси, thought leadership
B16: Люди | C16: Z04 | D16: Команда і культура | E16: • Найм і звільнення Head-рівня (CTO, Head of GIS, Head of Sales) | F16: NPS команди | G16: — | I16: CHRO + People team. CEO — лише культура і топ-менеджмент. | J16: ≥7 /10
E17: • Quarterly All-Hands: стан компанії, стратегія, культура
E18: • NPS команди — пульс-опитування щоквартально
B19: Гроші | C19: Z05 | D19: Фінансовий результат | E19: • Контроль P&L компанії щомісяця | F19: Revenue план/факт | G19: — | I19: CFO бере операційні фінанси. CEO — лише стратегічний P&L. | J19: план $
E20: • Затвердження бюджету і витрат >$5K
E21: • Цільові показники Revenue, Margin, Growth
B22: Стратегія | C22: Z06 | D22: Запуск нових напрямків | E22: • Ухвалення рішення про launch нового сервісу або ринку | F22: Нових напрямків запущено / рік | G22: — | I22: Product/Innovation team. CEO — лише портфельні рішення. | J22: ≥2 шт
E23: • Виділення ресурсів для R&D і нових продуктів
E24: • Go/No-go рішення по новим направленням
A26: ДЛЯ НОВОГО СПІВРОБІТНИКА · Прочитай перед першим місяцем роботи
B27: Що таке ця таблиця? | E27: Твій особистий операційний документ. Зони (Z01, Z02…) — все, за що ти відповідаєш у ролі «CEO / Founder». ПЛАН — норма, яку очікує компанія. ФАКТ — те, що ти виконуєш фактично кожен місяць. МАСШТАБ — що зміниться в твоїй ролі коли компанія виросте до 200 осіб.
B28: Операційна модель GIS-Point | E28: Sales → PM → Delivery → Finance. Sales приносить контракт. PM відповідає за маржинальність і виконання. Delivery виконує роботу. Finance контролює фінпоказники. Не переступай зони суміжних ролей без погодження.
B29: Щомісячний ритуал (до 5-го числа) | E29: 1) Заповни колонку ФАКТ по кожній зоні. 2) Постав статус: ✅ норма / ⚠️ відхилення / ❌ критично. 3) При ⚠️ або ❌ — обов'язковий коментар: що сталось + яка дія. 4) На місячному мітингу проходишся по своєму листу з керівником.
B30: Ескалація | E30: Зона ❌ більше 2 місяців підряд — ескалуй одразу, не чекай мітингу. При ⚠️ — план дій у коментарі протягом 24 год.

Sheet CTO
A2: GIS-POINT · CTO / TECHNOLOGY DEPT
A3: Блоки Гарніша: Реалізація · Стратегія · Люди | Онбординг + Щомісячний контроль | Модель: Sales → PM → Delivery → Finance
B5: 👥 Команда зараз (≈40 осіб): CTO + 5 developers (backend, frontend, GIS dev) | F5: 🚀 При масштабі 200 осіб: CTO → Engineering Managers → 40–60 developers у 3 product teams | I5: Місяць огляду: March 2026 | ✏️ Заповни ФАКТ → СТАТУС → КОМЕНТАР при ⚠️/❌
B6: БЛОК (ГАРНІШ) | C6: Z# | D6: ЗОНА ВІДПОВІДАЛЬНОСТІ | E6: КОНКРЕТНІ ОБОВ'ЯЗКИ | F6: KPI / МЕТРИКА | G6: ПЛАН (норма) | H6: ФАКТ (місяць) | I6: СТАТУС ✅⚠️❌ | J6: КОМЕНТАР / ДІЯ | K6: ПРИ МАСШТАБІ 200 👥 (що зміниться)
B7: Реалізація | C7: Z01 | D7: Архітектура і технічні стандарти | E7: • Визначення архітектури всіх продуктів і платформ | F7: Tech debt incidents / місяць | G7: ≤2 шт | I7: — | K7: Архітектори по доменах. CTO — лише cross-domain рішення і стандарти.
E8: • Вибір технологічного стеку і технічних стандартів команди
E9: • Code review архітектурних рішень (senior-рівень)
B10: Реалізація | C10: Z02 | D10: GIS Software Development | E10: • Керівництво розробкою GIS web і mobile додатків | F10: Sprint delivery rate (задачі в строк) | G10: ≥85 % | I10: — | K10: Engineering Managers по продуктах. CTO — лише технічна стратегія.
E11: • GIS platforms: spatial data, 3D viewers, satellite portals
E12: • API integration, IoT, GPS tracking системи
B13: Стратегія | C13: Z03 | D13: R&D і нові технології | E13: • AI / ML / computer vision для GIS-задач | F13: POC завершено в строк | G13: ≥80 % | I13: — | K13: R&D Lead / окремий підрозділ R&D з бюджетом.
E14: • GIS automation і data processing pipelines
E15: • POC нових технологій — рішення за 2 тижні
B16: Люди | C16: Z04 | D16: Управління IT-командою | E16: • 1-on-1 з кожним developer (bi-weekly) | F16: Developer satisfaction (internal NPS) | G16: ≥7 /10 | I16: — | K16: Engineering Managers. CTO управляє лише EM-рівнем.
E17: • Технічний онбординг нових розробників
E18: • Оцінка і розвиток технічних компетенцій команди
B19: Реалізація | C19: Z05 | D19: Технічна підтримка продажів | E19: • Технічна оцінка scope за 48 год після запиту від Sales | F19: Оцінки надано в строк | G19: ≥90 % | I19: — | K19: Solution Architects для пресейлу.
E20: • Участь у технічних презентаціях для клієнтів
E21: • Підготовка технічної частини пропозицій
A23: ДЛЯ НОВОГО СПІВРОБІТНИКА · Прочитай перед першим місяцем роботи
B24: Що таке ця таблиця? | E24: Твій особистий операційний документ. Зони (Z01, Z02…) — все, за що ти відповідаєш у ролі «CTO / Technology Dept». ПЛАН — норма, яку очікує компанія. ФАКТ — те, що ти виконуєш фактично кожен місяць. МАСШТАБ — що зміниться в твоїй ролі коли компанія виросте до 200 осіб.
B25: Операційна модель GIS-Point | E25: Sales → PM → Delivery → Finance. Sales приносить контракт. PM відповідає за маржинальність і виконання. Delivery виконує роботу. Finance контролює фінпоказники. Не переступай зони суміжних ролей без погодження.
B26: Щомісячний ритуал (до 5-го числа) | E26: 1) Заповни колонку ФАКТ по кожній зоні. 2) Постав статус: ✅ норма / ⚠️ відхилення / ❌ критично. 3) При ⚠️ або ❌ — обов'язковий коментар: що сталось + яка дія. 4) На місячному мітингу проходишся по своєму листу з керівником.
B27: Ескалація | E27: Зона ❌ більше 2 місяців підряд — ескалуй одразу, не чекай мітингу. При ⚠️ — план дій у коментарі протягом 24 год.

Sheet Head of Delivery
A2: GIS-POINT · HEAD OF DELIVERY
A3: Підпорядкування: CEO | Управляє: PM · GIS/BIM Engineers · Картографи | Модель: Sales → Head → Team → Finance
A4: Scope: GIS-Point (GIS Delivery)
B6: Місяць: March 2026 | E6: ✏️ Жовті клітинки = заповнюєш щомісяця: ФАКТ → СТАТУС (✅ / ⚠️ / ❌) → коментар при відхиленні
B7: БЛОК | C7: Z# | D7: ЗОНА ВІДПОВІДАЛЬНОСТІ | E7: ЩО ВХОДИТЬ / КОНКРЕТНІ ОБОВ'ЯЗКИ | F7: KPI / МЕТРИКА | G7: ПЛАН | H7: ФАКТ | I7: СТАТ. ✅⚠️❌ | J7: КОМЕНТАР / ДІЯ | K7: @200 осіб
A8: ▌ ЗОНИ ВІДПОВІДАЛЬНОСТІ (9 зон — відповідає особисто)
B9: Реалізація | C9: Z01 | D9: Виконання виробничих планів і термінів | E9: • Забезпечення виконання проектів у погоджені терміни і в рамках scope | F9: Проекти здані в строк | G9: ≥85 % | H9: 73% (11/15) | I9: ❌ | J9: 3 BIM-проекти — системна затримка (відділ не укомплектований). 1 — зміна дати замовником (договір). План: рішення по структурі BIM до кінця місяця. | K9: PMO контролює виконання. Head — портфельний рівень.
E10: • Щотижневий моніторинг статусу всіх активних проектів (RAG: 🟢🟡🔴)
E11: • Ескалація до CEO при ризику зриву термінів більше ніж на 1 тиждень
B12: Стратегія | C12: Z02 | D12: Формування архітектури відділу і команди | E12: • Визначення структури відділу: ролі, ієрархія, зони відповідальності | F12: Структура відділу відповідає поточному навантаженню | G12: quarterly review | I12: — | K12: VP Delivery формує архітектуру. Head — операційна структура.
E13: • Планування складу команди на 6–12 місяців відповідно до pipeline продажів
E14: • Рішення про поділ на суб-команди при зростанні (GIS / BIM / Cartography)
B15: Реалізація | C15: Z03 | D15: Прогнозованість завантаження команди | E15: • Capacity plan на 2 місяці вперед — синхронізація з Sales pipeline щотижня | F15: Utilization rate команди | G15: 75–90 % | H15: 0.86 | I15: ✅ | J15: В нормі. GIS/LiDAR — в діапазоні. BIM окремо не рахується через неукомплектованість. | K15: Resource Manager окремо.
E16: • Розподіл GIS/BIM engineers і картографів між проектами
E17: • Своєчасне рішення щодо залучення сабконтракторів при пікових навантаженнях
B18: Люди | C18: Z04 | D18: Навчання та покращення ефективності | E18: • Квартальний план навчання для кожного члена команди | F18: Learning plan виконано / квартал | G18: ≥80 % | H18: В процесі | I18: ⚠️ | J18: Навчання запущено, оплата Udemy (1 акаунт — тест) в процесі. Компенсація за англійську — запущено | K18: L&D функція окремо. Head — стратегія розвитку.
E19: • Впровадження нових інструментів і технологій у виробничий процес
E20: • Вимірювання продуктивності: output / людино-годину по кожному спеціалісту
E21: • Ретроспективи після проектів → конкретні покращення процесів
B22: Люди | C22: Z05 | D22: Найм та звільнення | E22: • Формування вимог до вакансії, проведення технічних інтерв'ю | F22: Відкриті вакансії закриті в строк | G22: ≤45 днів | H22: — | I22: — | K22: CHRO + HR BP. Head — фінальне рішення по технічних ролях.
E23: • Рішення про найм нових спеціалістів у межах затвердженого бюджету
E24: • Рішення про звільнення після документування причин і погодження з CEO
E25: • Найм помічника (асистента Head) — лише після погодження бюджету і моделі відповідальності з CEO
B26: Гроші | C26: Z06 | D26: Вплив на собівартість delivery | E26: • Оптимізація витрат часу команди на типові задачі (норми трудомісткості) | F26: Cost per project (факт vs норматив) | G26: ≤норм. год/₴ | I26: — | J26: Дані від фінансового відділу очікуються. | K26: CFO + FP&A контролюють. Head — операційний вплив.
E27: • Контроль витрат на підрядників, ліцензії ПЗ, обладнання
E28: • Пропозиції щодо автоматизації і стандартизації для зниження cost per project
B29: Гроші | C29: Z07 | D29: Дотримання маржі проектів | E29: • Маржа кожного проекту — контроль відповідно до заздалегідь узгодженого рівня | F29: Маржа проектів факт vs узгоджена | G29: ≥30 % | I29: — | J29: Дані від фінансового відділу очікуються. | K29: Project Controllers. Head — відповідальність за дотримання.
E30: • Звіт по маржі після закриття кожного проекту → передача до Finance
E31: • Ескалація до CEO якщо маржа падає нижче узгодженого порогу в процесі виконання
B32: Реалізація | C32: Z08 | D32: Виконання квартальних планів виробництва | E32: • Квартальний виробничий план: кількість проектів, revenue Delivery, utilization | F32: Квартальний план виробництва виконано | G32: ≥90 % | H32: Q2: 32% | I32: ❌ | J32: Q2 — 32% від плану ($113k / $352k). | K32: OKR система на рівні компанії.
E33: • Щомісячний звіт CEO: факт vs план по квартальних цілях
E34: • Коригування пріоритетів команди при відхиленні від квартального плану
B35: Реалізація | C35: Z09 | D35: Пресейл і підтримка Sales | E35: • Технічна оцінка scope для Sales ≤48 год після запиту | F35: Оцінки надано ≤48 год | G35: ≥90 % | H35: 74% (26/35) | I35: ❌ | J35: 9 оцінок із 35 надано з перевищенням 48 год. Найбільші затримки: Vermessungsbüro 13 днів, GEO net 11 днів, Lewis Brown 6 днів. | K35: Solution Architects окремо.
E36: • Участь у пресейл-дзвінках на великих або нестандартних проектах
E37: • Технічний опис сервісів і кейси для маркетингу
A39: ▌ ПІДПОРЯДКУВАННЯ CEO · Операційні стандарти — Head контролює виконання
B40: Реалізація | C40: S01 | D40: Стандартизація delivery-процесів | E40: • Єдині шаблони ведення проектів: kick-off, статус-апдейт, закриття | F40: Проекти ведуться за стандартним процесом | G40: 100 % | H40: В процесі | I40: — | J40: Таска до кінця 2 кварталу | K40: Process Owner окремо.
E41: • Playbook Delivery — актуальний, виконується командою, оновлюється щоквартально
E42: • Аудит дотримання процесів: мінімум раз на квартал
B43: Реалізація | C43: S02 | D43: Єдині правила управління проектами | E43: • PM методологія зафіксована і виконується всіма PM і Head | F43: PM методологія задокументована і актуальна | G43: quarterly review | I43: — | K43: PMO веде методологію.
...

Sheet Operations
A2: GIS-POINT · OPERATIONS & FINANCE
A3: Блоки Гарніша: Гроші · Люди · Реалізація | Онбординг + Щомісячний контроль | Модель: Sales → PM → Delivery → Finance
B5: 👥 Команда зараз (≈40 осіб): Finance + Admin (1–2 особи) + аутсорс-бухгалтер | F5: 🚀 При масштабі 200 осіб: CFO + CHRO + Legal Counsel + Finance team 3–5 осіб | I5: Місяць огляду: Мау2026 | ✏️ Заповни ФАКТ → СТАТУС → КОМЕНТАР при ⚠️/❌
B6: БЛОК (ГАРНІШ) | C6: Z# | D6: ЗОНА ВІДПОВІДАЛЬНОСТІ | E6: КОНКРЕТНІ ОБОВ'ЯЗКИ | F6: KPI / МЕТРИКА | G6: ПЛАН (норма) | H6: ФАКТ (місяць) | I6: СТАТУС ✅⚠️❌ | J6: КОМЕНТАР / ДІЯ | K6: ПРИ МАСШТАБІ 200 👥 (що зміниться)
B7: Гроші | C7: Z01 | D7: Фінансовий контроль | E7: • Щомісячний P&L для CEO (до 7-го числа) | F7: Прострочена дебіторка | G7: ≤10 % від AR | H7: на кінець місяця протермінована дебіторка становить 22146$ , що становить 70% від загальної дебіторки | I7: ❌ | K7: CFO + Finance team. Окремий FP&A аналітик.
E8: • Cash flow forecast 3 місяці rolling
E9: • Контроль дебіторської заборгованості (invoice → оплата)
B10: Гроші | C10: Z02 | D10: Інвойси, платежі, ЗП | E10: • Виставлення інвойсів клієнтам після підписання акту | F10: ЗП виплачено вчасно | G10: 100 % | H10: Зп нараховано та виплачено вчасно | I10: ✅ | K10: AR/AP manager як окрема роль.
E11: • Контроль і виплата ЗП до 7-го числа
E12: • Оплата рахунків підрядників і постачальників • Розрахунок ЗП для PM (Алевтина, Роман) і Sales команди щомісяця → зведена відомість
B13: Гроші | C13: Z03 | D13: Собівартість і маржа | E13: • Обрахунок cost per project (години × ставка + overhead) | F13: Маржа проектів (середня) | G13: ≥30 % | H13: Спостерігається значне відхилення по % показника EBIT ( середньо 16% замість 30% планових) | I13: ❌ | J13: Причиною є низький показник виконання плану по виробництву. Revenue у 112тис за два місяці не покриває у достатній кількості запланованих постійних витрат, які не залежать від обсягів виробництва. • Необхідно вивчити динаміку прогнозних показників виробництва на найближчі 2-3міс і прийняти рішення щодо перегляду бюджету | K13: Project Controller як окрема роль.
E14: • Маржинальність кожного проекту після завершення
E15: • Надання CEO | PM звіту по маржі щомісячний контроль
B16: Люди | C16: Z04 | D16: HR і адміністрація | E16: • Оформлення нових співробітників (договір, onboarding-документи) | F16: Onboarding завершено за ≤3 дні від старту | G16: 100 % | I16: — | K16: CHRO + HR Business Partners по відділах.
E17: • Відстеження відпусток, лікарняних, remote-графіку
E18: • HR-документообіг і трудові відносини
B19: Реалізація | C19: Z05 | D19: Юридична підтримка і контракти | E19: • Підготовка і погодження клієнтських контрактів | F19: Контракти підписані без юр. претензій | G19: 100 % | I19: — | K19: Legal Counsel (in-house або retained).
E20: • NDA, партнерські угоди, підрядні договори
E21: • Compliance з міжнародним правом (UK, EU)
B22: Гроші | C22: Z06 | D22: Бухгалтерія (аутсорс) і податки | E22: • Координація з аутсорс-бухгалтером по UA-звітності | F22: Штрафи / пені від ДПС | G22: 0 грн | H22: Вчасно подано річний фін звіт в UK, сплачено податок | I22: ✅ | K22: Фін. директор бере повний контроль над бух.
E23: • ПДВ, ЄСВ, ПДФО — здача в строк
E24: • Закриття звітних періодів і архів документів
D25: Доробити блок ЮК
A26: ДЛЯ НОВОГО СПІВРОБІТНИКА · Прочитай перед першим місяцем роботи
B27: Що таке ця таблиця? | E27: Твій особистий операційний документ. Зони (Z01, Z02…) — все, за що ти відповідаєш у ролі «Operations & Finance». ПЛАН — норма, яку очікує компанія. ФАКТ — те, що ти виконуєш фактично кожен місяць. МАСШТАБ — що зміниться в твоїй ролі коли компанія виросте до 200 осіб.
B28: Операційна модель GIS-Point | E28: Sales → PM → Delivery → Finance. Sales приносить контракт. PM відповідає за маржинальність і виконання. Delivery виконує роботу. Finance контролює фінпоказники. Не переступай зони суміжних ролей без погодження.
B29: Щомісячний ритуал (до 5-го числа) | E29: 1) Заповни колонку ФАКТ по кожній зоні. 2) Постав статус: ✅ норма / ⚠️ відхилення / ❌ критично. 3) При ⚠️ або ❌ — обов'язковий коментар: що сталось + яка дія. 4) На місячному мітингу проходишся по своєму листу з керівником.
B30: Ескалація | E30: Зона ❌ більше 2 місяців підряд — ескалуй одразу, не чекай мітингу. При ⚠️ — план дій у коментарі протягом 24 год.

Sheet PM
A2: GIS-POINT · PROJECT MANAGER
A3: Підпорядкування: Head of Delivery · Поточні PM: Алевтина, Роман · Відповідає за: scope, дедлайн, клієнт, маржа
B5: Місяць: March 2026 | E5: ✏️ Жовті клітинки = заповнюєш щомісяця: ФАКТ → СТАТУС (✅⚠️❌) → коментар при відхиленні
B6: БЛОК | C6: Z# | D6: ЗОНА | E6: ЩО ВХОДИТЬ | F6: KPI | G6: ПЛАН | H6: ФАКТ | I6: СТАТ. | J6: КОМЕНТАР / ДІЯ | K6: @200 осіб
B7: Реалізація | C7: Z01 | D7: Запуск проекту | E7: • Прийом briefing від Sales → kick-off call з клієнтом | F7: Kick-off проведено ≤5 днів після підписання | G7: 100 % | I7: — | K7: Окремі PM по напрямках (GIS PM, BIM PM)
E8: • Декомпозиція scope в задачі, milestones, розподіл по команді
E9: • Оцінка ризиків на старті, узгодження з Head of Delivery
B10: Реалізація | C10: Z02 | D10: Виконання і контроль | E10: • Постановка задач GIS/BIM engineers і картографам | F10: Blockers вирішені ≤24 год | G10: ≥90 % | I10: — | K10: Scrum Master окремо
E11: • Контроль дедлайнів: щотижневий прогрес по кожній задачі
E12: • Blockers — вирішення або ескалація до Head ≤24 год
B13: Реалізація | C13: Z03 | D13: Клієнт | E13: • Тижневий статус-апдейт клієнту: прогрес, ризики, наступні кроки | F13: Client CSAT після проекту | G13: ≥8 /10 | I13: — | K13: Client Success Manager окремо
E14: • Управління очікуваннями, фіксація всіх змін scope письмово
B15: Гроші | C15: Z04 | D15: Маржа і бюджет проекту | E15: • Контроль витрат проекту vs затверджений бюджет | F15: Маржа проекту факт | G15: ≥30 % | I15: — | K15: Project Controller окремо
E16: • Ескалація до Head при перевищенні бюджету >10%
E17: • Факт-маржа після закриття → передача до Finance
B18: Реалізація | C18: Z05 | D18: Закриття проекту | E18: • QA-прийомка результатів (чеклист) перед передачею клієнту | F18: Проект закрито з підписаним актом | G18: 100 % | I18: — | K18: Standardized closure через PMO
E19: • Підписаний акт від клієнта
E20: • Ретроспектива команди → lessons learned до Head
A22: ДЛЯ НОВОГО СПІВРОБІТНИКА · Прочитай перед першим місяцем роботи
A23: Що таке ця таблиця? | D23: Твій особистий операційний документ. Зони (Z01, Z02…) — все, за що ти відповідаєш у ролі «Project Manager». ПЛАН — норма, яку очікує компанія. ФАКТ — що ти реально виконуєш щомісяця. СТАТУС: ✅ норма / ⚠️ відхилення / ❌ критично.
A24: Операційна модель | D24: Лідогенератори → TL LeadGen → Sales Manager → PM → Delivery → Finance. Кожна ланка знає свій результат і не переходить зону сусіда без погодження.
A25: Щомісячний ритуал (до 5-го числа) | D25: 1) Заповни ФАКТ по кожній зоні (жовті клітинки). 2) Постав СТАТУС: ✅ / ⚠️ / ❌. 3) При ⚠️ або ❌ — напиши коментар: що сталось + яка дія. 4) На місячному мітингу проходишся по своєму листу з керівником.
A26: Ескалація | D26: ⚠️ → план дій у коментарі протягом 24 год. ❌ більше 2 місяців підряд → ескалуй одразу, не чекай мітингу.
A27: Твій результат | D27: Проект здається в строк, в бюджеті, клієнт задоволений (CSAT ≥8/10), акт підписаний. Кожна угода що прийшла від Sales → ти її ведеш від kick-off до закриття.

Sheet Sales
A2: GIS-POINT · SALES MANAGER · АНДРІЯНА
A3: Підпорядкування: CEO | Взаємодія: TL LeadGen · PM · Finance · Delivery
A4: Результат ролі: виконання плану продажів — підписані договори і задоволені клієнти
B6: Місяць: April 2026 | E6: ✏️ Жовті клітинки = заповнюєш щомісяця: ФАКТ → СТАТУС (✅ / ⚠️ / ❌) → коментар при відхиленні
B7: БЛОК | C7: Z# | D7: ЗОНА | E7: ЩО ВХОДИТЬ / ОБОВ'ЯЗКИ | F7: KPI · ПЛАН | G7: ФАКТ (місяць) | H7: СТАТ. ✅⚠️❌ | I7: КОМЕНТАР / ДІЯ
B8: Реалізація | C8: Z01 | D8: Пресейл-зустрічі та виявлення потреби | E8: • Проведення пресейл-зустрічі: виявлення болю, потреби, бюджету, DM, строків | F8: Пресейл-зустрічей / місяць: ≥план Sales Accepted Leads: ≥план | G8: 10 зустрічей (6 мої+ 4 очні Євген) | H8: ❌ | I8: Причина: недостатній обсяг лідів від команди лід-генів
E9: • Підтвердження: чи точно наш клієнт (ICP відповідає, є бюджет і потреба)
E10: • Agenda зустрічі: підготовка заздалегідь, чіткі питання, підсумок після
E11: • Рішення після зустрічі: рухаємось до ТЗ / відкладаємо / закриваємо як нецільового
B12: Реалізація | C12: Z02 | D12: Отримання ТЗ та формування пропозиції | E12: • Збір технічного завдання від клієнта або допомога у його формулюванні | F12: ТЗ отримано / місяць: ≥план Пропозицій відправлено: ≥план | G12: ТЗ отримано: 37 | Пропозицій відправлено: 28 | Відмов: 3 (Axitera — не наша експертиза, GEOFLY — роблять in-house, Serhii_R — терміни) | H12: ✅ | I12: Перевиконання плану (план 11). 37 запитів, 28 пропозицій, 8 взято в роботу, 3 відмови (2 об'єктивні — не наша експертиза / in-house, 1 — терміни).
E13: • Погодження scope і термінів з PM / CTO / Head of GIS перед пропозицією
E14: • Підготовка і презентація комерційної пропозиції
E15: • Захист пропозиції: відповіді на заперечення, коригування умов
B16: Гроші | C16: Z03 | D16: Closing і підписання договорів | E16: • Ведення переговорів: заперечення, умови, знижки — в межах погодженого з CEO | F16: Revenue closed / місяць: ≥план $ Win rate: ≥20% Договорів підписано: ≥план шт | G16: Revenue closed: $72,665 | Договорів: 13 шт | Win rate: 44% | H16: ⚠️ | I16: Недовиконання по revenue — $72,665 з плану $165,764 (44%). Основна причина gap — не вистачає великих угод. Тендери тягнуть основний обсяг. Дія: фокус на травень! на pipeline з великим чеком компанії з тендерів.
E17: • Підписання договору: координація з Finance для перевірки умов
E18: • Контракти >$100K — обов'язкове погодження з CEO перед підписанням
E19: • Контроль виконання плану продажів — ескалація до CEO якщо нижче 80%
B20: Реалізація | C20: Z04 | D20: Ведення угод у CRM (повний цикл) | E20: • CRM: кожна угода на актуальній стадії — оновлення кожного понеділка | F20: CRM актуальна: 100% Forecast accuracy: ≥75% Win/Loss аналіз: щомісяця | G20: CRM актуальність: 100% Forecast accuracy: є Win/Loss аналіз: заповнено | H20: ✅ | I20: Всі угоди актуальні, Win/Loss аналіз за квітень виконано.
E21: • Follow-up лідів на повному циклі: жоден ліад не залишається без наступного кроку
E22: • Щомісячний forecast CEO: скільки очікуємо закрити і коли
E23: • Win/Loss аналіз: чому програли — зафіксувати і передати TL для коригування ICP
B24: Гроші | C24: Z05 | D24: Робота з існуючими клієнтами | E24: • Апсели і крос-сели: виявлення нових потреб у поточних клієнтів | F24: NRR (Net Revenue Retention): ≥100% Контракти продовжено вчасно: 100% | G24: NRR: 100%+ | Контракти продовжено вчасно: 100% (GEO4EVER $26,297 + GlobeZenit $900 = $27,197) | Апсели/крос-сели: запущено | Очні зустрічі: в плануванні після повернення Євгена | H24: ✅ | I24: Два контракти продовжено вчасно на $27,197. Апсели активні з поточними клієнтами.
E25: • Продовження контрактів: нагадування за 30 днів до закінчення
E26: • Збір фідбеку і робота із запереченнями — підвищення рівня задоволеності
E27: • Постійна комунікація: клієнт завжди знає хто відповідає за його акаунт
B28: Реалізація | C28: Z06 | D28: Взаємодія з Delivery та Finance | E28: • Handoff PM після підписання: client brief + kick-off call у перший тиждень | F28: Handoff без повернень питань до Sales: ≥90% Звіт ЗП: до 3-го числа | G28: Handoff без повернень: 100% | Звіт ЗП: здано вчасно (до 4-го) | H28: ✅ | I28: Всі handoff чисті, питань від Delivery не було. Звіт ЗП здано вчасно.
E29: • Участь у пресейлах разом з PM / CTO для технічних клієнтів
E30: • Формування звіту ЗП відділу продажів щомісяця → Finance
E31: • Фідбек Delivery: що можна обіцяти клієнтам, що ні — щомісяця
B32: Реалізація | C32: Z07 | D32: Інтеграції та ОДДО | E32: • Узгодження і адаптація ОДДО (опис документообігу / delivery) з інтеграторами | F32: Проекти з інтеграторами без операційних збоїв: 100% | G32: ОДДО на паузі (CEO) | H32: ⚠️ | I32: —
E33: • Координація на всіх етапах реалізації: Sales ↔ PM ↔ клієнт
E34: • Фіксація всіх змін в умовах договору та узгодження з командою
B36: Що таке ця таблиця? | E36: Твій особистий операційний документ. Зони (Z01, Z02…) — все, за що ти відповідаєш у ролі «Sales & Business Dev». ПЛАН — норма, яку очікує компанія. ФАКТ — те, що ти виконуєш фактично кожен місяць. МАСШТАБ — що зміниться в твоїй ролі коли компанія виросте до 200 осіб.
B37: Операційна модель GIS-Point | E37: Sales → PM → Delivery → Finance. Sales приносить контракт. PM відповідає за маржинальність і виконання. Delivery виконує роботу. Finance контролює фінпоказники. Не переступай зони суміжних ролей без погодження.
B38: Щомісячний ритуал (до 5-го числа) | E38: 1) Заповни колонку ФАКТ по кожній зоні. 2) Постав статус: ✅ норма / ⚠️ відхилення / ❌ критично. 3) При ⚠️ або ❌ — обов'язковий коментар: що сталось + яка дія. 4) На місячному мітингу проходишся по своєму листу з керівником.

Sheet Team Lead LM
A2: GIS-POINT · TEAM LEAD · ЛІДОГЕНЕРАЦІЯ
A3: Підпорядкування: Sales Lead / CEO | Управляє: 3–4 лід-ген менеджери
A4: Результат ролі: стабільні ≥21 зустріч/місяць → масштаб до 30 · Якість лідів ≥4/5
B6: Місяць: April 2026 | E6: ✏️ Жовті клітинки = заповнюєш щомісяця: ФАКТ → СТАТУС (✅ / ⚠️ / ❌) → коментар при відхиленні
B7: БЛОК | C7: Z# | D7: ЗОНА | E7: ЩО ВХОДИТЬ / ОБОВ'ЯЗКИ | F7: KPI · ПЛАН | G7: ФАКТ (місяць) | H7: СТАТ. ✅⚠️❌ | I7: КОМЕНТАР / ДІЯ
B8: Люди | C8: Z01 | D8: Управління командою лідогенераторів | E8: • Розподіл задач і пріоритетів між менеджерами по ICP і сегментах | F8: Команда виконує план по зустрічах: ≥80% місяців Team NPS: ≥7/10 | H8: —
E9: • Щоденний standup (10 хв): темп, блокери, якість — вирішення, не звіт
E10: • 1-on-1 bi-weekly з кожним менеджером: продуктивність, розвиток, фідбек
E11: • Контроль виконання тижневих і місячних цілей кожного менеджера
E12: • Найм та звільнення менеджерів, ініціалізацію проводить TL
B13: Люди | C13: Z02 | D13: Навчання та онбординг | E13: • Онбординг нового лідогенератора: 30-денний план виходу на норму | F13: Новий менеджер на нормі: ≤45 днів Щотижневий розбір: 100% | H13: —
E14: • Щотижневий разбір кейсу: що спрацювало / не спрацювало і чому
E15: • Коучинг по конкретних переписках — разом розбирати reply і відмови
E16: • Розвиток компетенцій: нові техніки персоналізації, research акаунтів
B17: Реалізація | C17: Z03 | D17: Кампанії та сіквенси | E17: • Запуск і моніторинг outbound кампаній (Email + LinkedIn) по ICP-сегментах | F17: Reply rate: ≥8% Bounce rate: ≤3% A/B тестів / міс: ≥2 Sіквенси оновлені: щомісяця | H17: —
E18: • Написання і оновлення сіквенсів: персоналізований перший рядок, чіткий CTA
E19: • A/B тести: subject line, меседж, ICP — ≥2 тести на місяць
E20: • Оптимізація активних кампаній на основі даних (не відчуттів)
E21: • Прогрів і моніторинг акаунтів: bounce ≤3%, deliverability в нормі
B22: Якість | C22: Z04 | D22: Контроль якості лідів і відповідності ICP | E22: • Оцінка кожного ліда перед передачею в Sales: 4/5 або 5/5 — не менше | F22: Якість ліда (avg): ≥4/5 Скасованих зустрічей через низьку якість ліда: ≤10% | H22: —
E23: • Критерії оцінки: відповідність ICP, підтверджений інтерес, наявність DM
E24: • Щотижневий sampling повідомлень команди (≥3 на менеджера)
E25: • Feedback від Sales після зустрічей → коригування ICP або підходу
B26: Аналітика | C26: Z05 | D26: Аналітика і звітність | E26: • Тижневий звіт: Outreach → Reply → Booking → Meetings — по кожному менеджеру | F26: Тижневий звіт: щопонеділка до 10:00 Місячний звіт: до 3-го числа CRM актуальна: 100% | H26: —
E27: • Місячний звіт Sales Lead / CEO: факт vs план, конверсії, гіпотези, наступний місяць
E28: • Аналіз воронки: де відсів найбільший і що з цим робимо
E29: • CRM актуальна: всі стадії оновлені, картки заповнені
B30: Реалізація | C30: Z06 | D30: Гіпотези та оптимізація | E30: • ≥2 гіпотези на місяць: сегмент + меседж + очікувана конверсія + вибірка | F30: Гіпотез / міс: ≥2 Впроваджено в команду: ≥1 / квартал | H30: —
E31: • Тестування нових каналів, ICP, підходів — з документованим результатом
E32: • Реєстр гіпотез: всі (включно з невдалими) задокументовані
E33: • Кращі підходи — впроваджені в роботу всієї команди
B34: Реалізація | C34: Z07 | D34: Автоматизація та інструменти | E34: • Налаштування і підтримка outreach-інструментів (Apollo, Instantly, Lemlist тощо) | F34: Час менеджера на outreach: ≥70% Nові інструменти: тестуємо ≥1/квартал | H34: —
E35: • Автоматизація рутини: follow-up, enrichment, верифікація — менеджер ≥70% часу на outreach
E36: • Впровадження нових AI-інструментів при потребі
B37: Реалізація | C37: Z08 | D37: Івенти, виставки, конференції | E37: • Підготовка до участі: список цільових контактів, меседж, мета | F37: Leads від івентів / квартал: ≥5 Booking rate від івент-лідів: ≥30% | H37: —
E38: • Outreach до учасників до і після події
E39: • Конвертація нетворкінгу в booking: кожен контакт → стадія в CRM
A41: ДЛЯ НОВОГО СПІВРОБІТНИКА · Прочитай перед першим місяцем роботи
A42: Що таке ця таблиця? | D42: Твій особистий операційний документ. Зони (Z01, Z02…) — все, за що ти відповідаєш у ролі «Team Lead Лідогенерації». ПЛАН — норма, яку очікує компанія. ФАКТ — що ти реально виконуєш щомісяця. СТАТУС: ✅ норма / ⚠️ відхилення / ❌ критично.
A43: Операційна модель | D43: Лідогенератори → TL LeadGen → Sales Manager → PM → Delivery → Finance. Кожна ланка знає свій результат і не переходить зону сусіда без погодження.
...

Sheet GIS-BIM Engineer
A1: ,
A2: GIS-POINT · GIS / BIM ENGINEER
A3: Підпорядкування: PM (задачі) / Head of Delivery (розвиток) · Виробнича роль: виконання і якість
B5: Місяць: March 2026 | E5: ✏️ Жовті клітинки = заповнюєш щомісяця: ФАКТ → СТАТУС (✅⚠️❌) → коментар при відхиленні
B6: БЛОК | C6: Z# | D6: ЗОНА | E6: ЩО ВХОДИТЬ | F6: KPI | G6: ПЛАН | H6: ФАКТ | I6: СТАТ. | J6: КОМЕНТАР / ДІЯ | K6: @200 осіб
B7: Реалізація | C7: Z01 | D7: Виконання задач | E7: • Виконання GIS/BIM/картографічних задач згідно ТЗ і дедлайну | F7: Задачі здані в строк | G7: ≥90 % | I7: — | K7: Team Lead координує 5–8 інженерів
E8: • LiDAR processing, spatial analysis, CAD/BIM modeling, mapping — за спеціалізацією
E9: • Щоденне оновлення прогресу в task tracker
B10: Реалізація | C10: Z02 | D10: Якість результату | E10: • Самоперевірка перед здачею PM (за internal checklist) | F10: Revision requests по своїх задачах | G10: ≤2 шт/міс | I10: — | K10: QA Engineer перевіряє вихідний результат
E11: • Врахування feedback від PM і клієнта без повторних помилок
E12: • Дотримання стандартів і форматів вихідних файлів
B13: Люди | C13: Z03 | D13: Комунікація і командна робота | E13: • Сигналізувати PM про блокер або затримку одразу (не в дедлайн) | F13: Блокери повідомлені PM ≤4 год після виявлення | G13: 100 % | I13: — | K13: Peer review між інженерами
E14: • Допомога колегам при пікових завантаженнях за запитом PM
E15: • Участь у ретроспективі проекту
B16: Стратегія | C16: Z04 | D16: Розвиток компетенцій | E16: • Освоєння нових інструментів за планом Head of Delivery | F16: Learning plan виконано за квартал | G16: ≥80 % | I16: — | K16: Спеціалізація по вертикалях (LiDAR Expert, BIM Lead тощо)
E17: • Участь у внутрішніх tech-сесіях і R&D ініціативах
E18: • Документування нових методів і підходів для команди
A20: ДЛЯ НОВОГО СПІВРОБІТНИКА · Прочитай перед першим місяцем роботи
A21: Що таке ця таблиця? | D21: Твій особистий операційний документ. Зони (Z01, Z02…) — все, за що ти відповідаєш у ролі «GIS / BIM Engineer». ПЛАН — норма, яку очікує компанія. ФАКТ — що ти реально виконуєш щомісяця. СТАТУС: ✅ норма / ⚠️ відхилення / ❌ критично.
A22: Операційна модель | D22: Лідогенератори → TL LeadGen → Sales Manager → PM → Delivery → Finance. Кожна ланка знає свій результат і не переходить зону сусіда без погодження.
A23: Щомісячний ритуал (до 5-го числа) | D23: 1) Заповни ФАКТ по кожній зоні (жовті клітинки). 2) Постав СТАТУС: ✅ / ⚠️ / ❌. 3) При ⚠️ або ❌ — напиши коментар: що сталось + яка дія. 4) На місячному мітингу проходишся по своєму листу з керівником.
A24: Ескалація | D24: ⚠️ → план дій у коментарі протягом 24 год. ❌ більше 2 місяців підряд → ескалуй одразу, не чекай мітингу.
A25: Твій результат | D25: Задачі здаються в строк і без revision requests. Ти сам перевіряєш свою роботу перед здачею PM (internal checklist). Блокери повідомляєш одразу — не в дедлайн.
A26: Інструменти (приклади за спеціалізацією) | D26: GIS: QGIS, ArcGIS, GRASS, SAGA. LiDAR: LAStools, CloudCompare, TerraSolid. CAD/BIM: AutoCAD, Revit, Civil 3D. Remote Sensing: ERDAS, ENVI, Google Earth Engine. Конкретний стек — уточнюй у Head of Delivery при онбордингу.

Sheet Lead gen. manager
A2: GIS-POINT · ЛІДОГЕНЕРАТОР · LEAD GEN MANAGER
A3: Підпорядкування: TL LeadGen | Канали: LinkedIn · Email · Івенти
A4: Результат ролі: заброньовані зустрічі з релевантними лідами (≥4/5) для Sales Manager
B6: Місяць: April 2026 | E6: ✏️ Жовті клітинки = заповнюєш щомісяця: ФАКТ → СТАТУС (✅ / ⚠️ / ❌) → коментар при відхиленні
B7: БЛОК | C7: Z# | D7: ЗОНА | E7: ЩО ВХОДИТЬ / ОБОВ'ЯЗКИ | F7: KPI · ПЛАН | G7: ФАКТ (місяць) | H7: СТАТ. ✅⚠️❌ | I7: КОМЕНТАР / ДІЯ
B8: Реалізація | C8: Z01 | D8: Outreach — LinkedIn та Email | E8: • Щоденний outreach: персоналізовані повідомлення по заданому ICP-сегменту | F8: Повідомлень / тиждень: ≥план Reply rate: ≥8% | H8: —
E9: • LinkedIn: connection request + перше повідомлення + follow-up (3–5 кроків)
E10: • Email: сіквенс за шаблоном TL з персоналізованим першим рядком
E11: • Ніколи не використовувати шаблонний / «роботизований» перший рядок
B12: Реалізація | C12: Z02 | D12: Кваліфікація і booking зустрічі | E12: • Первинна кваліфікація: чи відповідає ліда ICP, чи є інтерес і DM | F12: Meetings booked / місяць: ≥план Оцінка переданих лідів: ≥4/5 avg | H12: —
E13: • Booking: домовитись на зустріч (онлайн або фізичну) — чіткий час і agenda
E14: • Оцінити ліда перед передачею: 4/5 або 5/5 (нижче — не передавати)
E15: • Критерії оцінки 5/5: ICP ✓ + DM ✓ + Інтерес ✓ + Бюджет/потреба ✓ + Строки ✓ • Критерії 4/5: ICP ✓ + DM ✓ + Інтерес ✓ + (Бюджет АБО Строки підтверджені)
B16: Якість | C16: Z03 | D16: Якість комунікації | E16: • Перший рядок — завжди на основі research: сайт, LinkedIn, новини компанії | F16: Sampling TL: 0 критичних зауважень після review Bounce rate: ≤3% | H16: —
E17: • Не надсилати масові розсилки без персоналізації
E18: • При відмові — зафіксувати причину в CRM і не турбувати знову ≥3 місяці
E19: • Тон: professional, коротко, по суті — без «сподіваюся цей лист застане вас»
B20: Аналітика | C20: Z04 | D20: CRM і звітність | E20: • CRM оновлюється щодня: стадія, дата останнього контакту, нотатки | F20: CRM заповнена: 100% карток Щотижневий звіт: в строк | H20: —
E21: • Кожен ліда має заповнену картку: компанія, контакт, джерело, стадія, оцінка
E22: • Щотижневий звіт TL: Outreach / Reply / Booking / Meetings — факт тижня
E23: • Self-review місяця: що спрацювало / що ні / що б змінив
B24: Люди | C24: Z05 | D24: Розвиток і навчання | E24: • Участь у щотижневому розборі кейсів з TL | F24: Learning plan: ≥80% за квартал Блокери повідомлені: ≤4 год після виявлення | H24: —
E25: • Самостійно тестувати нові підходи до персоналізації
E26: • Фіксувати що спрацьовує — ділитись з командою
E27: • Вчасно сигналізувати TL про блокери (не в дедлайн)
A29: ДЛЯ НОВОГО СПІВРОБІТНИКА · Прочитай перед першим місяцем роботи
A30: Що таке ця таблиця? | D30: Твій особистий операційний документ. Зони (Z01, Z02…) — все, за що ти відповідаєш у ролі «Lead Gen Manager». ПЛАН — норма, яку очікує компанія. ФАКТ — що ти реально виконуєш щомісяця. СТАТУС: ✅ норма / ⚠️ відхилення / ❌ критично.
A31: Операційна модель | D31: Лідогенератори → TL LeadGen → Sales Manager → PM → Delivery → Finance. Кожна ланка знає свій результат і не переходить зону сусіда без погодження.
A32: Щомісячний ритуал (до 5-го числа) | D32: 1) Заповни ФАКТ по кожній зоні (жовті клітинки). 2) Постав СТАТУС: ✅ / ⚠️ / ❌. 3) При ⚠️ або ❌ — напиши коментар: що сталось + яка дія. 4) На місячному мітингу проходишся по своєму листу з керівником.
A33: Ескалація | D33: ⚠️ → план дій у коментарі протягом 24 год. ❌ більше 2 місяців підряд → ескалуй одразу, не чекай мітингу.
A34: Твій результат | D34: Заброньовані зустрічі з релевантними лідами (≥4/5) для Sales Manager. CRM заповнена щодня. Ти не передаєш ліда якщо він не відповідає критеріям 4/5 — навіть якщо дуже хочеться.
A35: Що значить якісний ліад | D35: 5/5: ICP ✓ + Decision Maker ✓ + Підтверджений інтерес ✓ + Бюджет ✓ + Строки ✓ 4/5: є мінімум 4 з 5 критеріїв — можна передавати. 3/5 і менше: продовжуй прогрівати або закрий як нецільового.

Sheet Marketing
A2: GIS-POINT · MARKETING
A3: Блоки Гарніша: Стратегія · Реалізація | Онбординг + Щомісячний контроль | Модель: Sales → PM → Delivery → Finance
B5: 👥 Команда зараз (≈40 осіб): 1 Marketer (generalist) | F5: 🚀 При масштабі 200 осіб: Marketing team: Content, SEO, Design, PR, Growth — 5–7 осіб + CMO | I5: Місяць огляду: March 2026 | ✏️ Заповни ФАКТ → СТАТУС → КОМЕНТАР при ⚠️/❌
B6: БЛОК (ГАРНІШ) | C6: Z# | D6: ЗОНА ВІДПОВІДАЛЬНОСТІ | E6: КОНКРЕТНІ ОБОВ'ЯЗКИ | F6: KPI / МЕТРИКА | G6: ПЛАН (норма) | H6: ФАКТ (місяць) | I6: СТАТУС ✅⚠️❌ | J6: КОМЕНТАР / ДІЯ | K6: ПРИ МАСШТАБІ 200 👥 (що зміниться)
B7: Стратегія | C7: Z01 | D7: Позиціонування і контент | E7: • Website: актуальний опис сервісів, кейси, індустрії | F7: Нових case studies / місяць | G7: ≥1 шт | I7: — | K7: Content team: copywriter, designer, videographer.
E8: • Case studies: мінімум 1 новий кейс / місяць
E9: • Social media: LinkedIn (основний канал) — 8+ постів / місяць
