Workbook

Sheet 1.Припущення
A1: ПРИПУЩЕННЯ — жовті комірки редагуються, решта рахується формулами
A2: Редакція 3: денні ставки — ФАКТИЧНІ дані власника. Експорт вилучено з аналізу.
A4: Параметр | B4: 2026 | C4: 2027 | D4: 2028 | E4: 2029 | F4: Джерело / коментар
A5: Курс USD/UAH | B5: 45 | C5: 47.5 | D5: 49.5 | E5: 51.5 | F5: НБУ серпень 2026
A6: Робочих днів, польова бригада | B6: 230 | C6: 230 | D6: 230 | E6: 230 | F6: 250 мінус відпустки/лікарняні
A7: Робочих днів, бурова бригада | B7: 210 | C7: 210 | D7: 210 | E7: 210 | F7: сезонність, доступ на майданчики
A8: Оплачуваних годин на IT-інженера | B8: 1459 | C8: 1459 | D8: 1459 | E8: 1459 | F8: 1 780 x 82% utilization
A10: A. ГЕОДЕЗИЧНА БРИГАДА — ринкова ціна і ДВІ структури витрат
A11: Стаття | B11: «Важка» структура | C11: «Легка» структура | F11: Коментар
A12: Денна ставка клієнту, грн | B12: 15000 | C12: 15000 | F12: ФАКТ власника, разом із камеральною обробкою
A13: Utilization — поточний стан | B13: 0.62 | C13: 0.62
A14: Utilization — цільовий | B14: 0.75 | C14: 0.75
A15: ФОП бригади, грн/рік | B15: 984000 | C15: 840000 | F15: штат проти ФОП
A16: Камеральна обробка, грн/рік | B16: 264000 | C16: 162000
A17: Авто, грн/рік | B17: 264000 | C17: 180000 | F17: лізинг проти власного
A18: Амортизація приладів, грн/рік | B18: 495000 | C18: 270000 | F18: нове $55к проти самортизованого
A19: ПЗ, ліцензії, повірки, грн/рік | B19: 96000 | C19: 60000
A20: Змінні на польовий день, грн | B20: 1400 | C20: 1200
A22: B. БУРОВА БРИГАДА — ТРИ структури витрат
A23: Стаття | B23: Повна (нова УРБ) | C23: Самортизована УРБ | D23: Мінімальна (2 особи) | F23: Коментар
A24: Денна ставка клієнту, грн | B24: 70000 | C24: 70000 | D24: 70000 | F24: ФАКТ власника: буріння + лабораторія + звіт
A25: ФОП бригади, грн/рік | B25: 1488000 | C25: 1488000 | D25: 1104000 | F25: 3 особи проти 2
A26: Інженер-геолог + звіт, грн/рік | B26: 504000 | C26: 504000 | D26: 504000
A27: Амортизація/лізинг УРБ, грн/рік | B27: 675000 | C27: 0 | D27: 0 | F27: $90к / 6 років проти списаної
A28: Ремонт і ТО, грн/рік | B28: 240000 | C28: 240000 | D28: 240000
A29: ПЗ, дозволи, ліцензії, грн/рік | B29: 84000 | C29: 84000 | D29: 84000
A30: Змінні на день, грн | B30: 5000 | C30: 5000 | D30: 5000
A31: Лабораторія, % від виручки | B31: 0.12 | C31: 0.12 | D31: 0.12
A33: C. IT-ІНЖЕНЕР
A34: Стаття | B34: Значення | C34: Од. | F34: Коментар
A35: ЗП, cost-to-company | B35: 3100 | C35: $/міс | F35: ринок 2026: $1 000-5 500 за роллю
A36: Податки, ЄСВ, адміністрування ФОП | B36: 0.06 | C36: % від ЗП
A37: Робоче місце, обладнання, ПЗ | B37: 450 | C37: $/міс
A38: Розподіл non-billable ролей | B38: 0.18 | C38: % від ЗП
A40: D. ПІДПИСКИ
A41: Модель | B41: ARPA $/рік | C41: Gross margin | D41: CAC $ | E41: Річний churn | F41: Коментар
A42: D1 SaaS — мережі й інфраструктурні активи | B42: 14000 | C42: 0.78 | D42: 8500 | E42: 0.12 | F42: увага: CloudCity уже у водоканалах
A43: D2 DaaS-моніторинг обʼєкта | B43: 6670 | C43: 0.72 | D43: 1800 | E43: 0.2 | F43: продається наявним клієнтам геодезії
A44: D3 Агро-продукт | B44: 9000 | C44: 0.7 | D44: 16000 | E44: 0.22 | F44: Cropio, OneSoil, Soft.Farm — ринок зайнятий

Sheet 2.Юніт-економіка
A1: ЮНІТ-ЕКОНОМІКА — усе рахується з аркуша «1.Припущення»
A3: A. ГЕОДЕЗІЯ: та сама ринкова ціна, дві структури витрат
A4: Показник | B4: «Важка» | C4: «Легка»
A5: Фіксовані витрати, грн/рік | B5: =('1.Припущення'!B15+'1.Припущення'!B16+'1.Припущення'!B17+'1.Припущення'!B18+'1.Припущення'!B19) | C5: =('1.Припущення'!C15+'1.Припущення'!C16+'1.Припущення'!C17+'1.Припущення'!C18+'1.Припущення'!C19)
A6: Точка беззбитковості, днів | B6: =('1.Припущення'!B15+'1.Припущення'!B16+'1.Припущення'!B17+'1.Припущення'!B18+'1.Припущення'!B19)/('1.Припущення'!B12-'1.Припущення'!B20) | C6: =('1.Припущення'!C15+'1.Припущення'!C16+'1.Припущення'!C17+'1.Припущення'!C18+'1.Припущення'!C19)/('1.Припущення'!B12-'1.Припущення'!C20)
A7: Точка беззбитковості, % utilization | B7: =B6/'1.Припущення'!B6 | C7: =C6/'1.Припущення'!B6
A8: @62%: виручка | B8: ='1.Припущення'!B6*'1.Припущення'!B13*'1.Припущення'!B12 | C8: ='1.Припущення'!B6*'1.Припущення'!B13*'1.Припущення'!B12
A9: @62%: витрати | B9: =('1.Припущення'!B15+'1.Припущення'!B16+'1.Припущення'!B17+'1.Припущення'!B18+'1.Припущення'!B19)+'1.Припущення'!B6*'1.Припущення'!B13*'1.Припущення'!B20 | C9: =('1.Припущення'!C15+'1.Припущення'!C16+'1.Припущення'!C17+'1.Припущення'!C18+'1.Припущення'!C19)+'1.Припущення'!B6*'1.Припущення'!B13*'1.Припущення'!C20
A10: @62%: ВАЛОВИЙ ПРИБУТОК | B10: =B8-B9 | C10: =C8-C9
A11: @62%: GM | B11: =B10/B8 | C11: =C10/C8
A12: @75%: виручка | B12: ='1.Припущення'!B6*'1.Припущення'!B14*'1.Припущення'!B12 | C12: ='1.Припущення'!B6*'1.Припущення'!B14*'1.Припущення'!B12
A13: @75%: витрати | B13: =('1.Припущення'!B15+'1.Припущення'!B16+'1.Припущення'!B17+'1.Припущення'!B18+'1.Припущення'!B19)+'1.Припущення'!B6*'1.Припущення'!B14*'1.Припущення'!B20 | C13: =('1.Припущення'!C15+'1.Припущення'!C16+'1.Припущення'!C17+'1.Припущення'!C18+'1.Припущення'!C19)+'1.Припущення'!B6*'1.Припущення'!B14*'1.Припущення'!C20
A14: @75%: ВАЛОВИЙ ПРИБУТОК | B14: =B12-B13 | C14: =C12-C13
A15: @75%: GM | B15: =B14/B12 | C15: =C14/C12
A16: Різниця «легка» − «важка» при 62% завантаження, грн/рік | B16: =C10-B10
A19: B. ГЕОЛОГІЯ: за якої ставки бригада виходить у нуль?
A20: Ставка, грн/бригадо-день | B20: Внесок на день | C20: Повна (нова УРБ) | D20: Самортизована УРБ | E20: Мінімальна (2 особи)
A21: 40000 | B21: =A21-'1.Припущення'!B30-A21*'1.Припущення'!B31 | C21: =('1.Припущення'!B25+'1.Припущення'!B26+'1.Припущення'!B27+'1.Припущення'!B28+'1.Припущення'!B29)/$B$21 | D21: =('1.Припущення'!C25+'1.Припущення'!C26+'1.Припущення'!C27+'1.Припущення'!C28+'1.Припущення'!C29)/$B$21 | E21: =('1.Припущення'!D25+'1.Припущення'!D26+'1.Припущення'!D27+'1.Припущення'!D28+'1.Припущення'!D29)/$B$21
A22: 55000 | B22: =A22-'1.Припущення'!B30-A22*'1.Припущення'!B31 | C22: =('1.Припущення'!B25+'1.Припущення'!B26+'1.Припущення'!B27+'1.Припущення'!B28+'1.Припущення'!B29)/$B$22 | D22: =('1.Припущення'!C25+'1.Припущення'!C26+'1.Припущення'!C27+'1.Припущення'!C28+'1.Припущення'!C29)/$B$22 | E22: =('1.Припущення'!D25+'1.Припущення'!D26+'1.Припущення'!D27+'1.Припущення'!D28+'1.Припущення'!D29)/$B$22
A23: 70000 | B23: =A23-'1.Припущення'!B30-A23*'1.Припущення'!B31 | C23: =('1.Припущення'!B25+'1.Припущення'!B26+'1.Припущення'!B27+'1.Припущення'!B28+'1.Припущення'!B29)/$B$23 | D23: =('1.Припущення'!C25+'1.Припущення'!C26+'1.Припущення'!C27+'1.Припущення'!C28+'1.Припущення'!C29)/$B$23 | E23: =('1.Припущення'!D25+'1.Припущення'!D26+'1.Припущення'!D27+'1.Припущення'!D28+'1.Припущення'!D29)/$B$23
A24: 85000 | B24: =A24-'1.Припущення'!B30-A24*'1.Припущення'!B31 | C24: =('1.Припущення'!B25+'1.Припущення'!B26+'1.Припущення'!B27+'1.Припущення'!B28+'1.Припущення'!B29)/$B$24 | D24: =('1.Припущення'!C25+'1.Припущення'!C26+'1.Припущення'!C27+'1.Припущення'!C28+'1.Припущення'!C29)/$B$24 | E24: =('1.Припущення'!D25+'1.Припущення'!D26+'1.Припущення'!D27+'1.Припущення'!D28+'1.Припущення'!D29)/$B$24
A25: Доступних робочих днів на рік → | B25: ='1.Припущення'!B7
A26: Читати так: якщо число днів БІЛЬШЕ за 210 — беззбитковість недосяжна за жодного завантаження.
A27: За фактичною ставкою 70 000 грн бригада виходить у нуль на 53 дні (25% завантаження) навіть із новою УРБ у лізингу.
A30: B2. ГЕОЛОГІЯ: результат за завантаженням (повна структура витрат)
A31: Utilization | B31: Оплач. днів | C31: Виручка | D31: Витрати | E31: ВАЛОВИЙ ПРИБУТОК | F31: GM | G31: ВП на 1 FTE, $
A32: 0.45 | B32: ='1.Припущення'!B7*A32 | C32: =B32*'1.Припущення'!B24 | D32: =('1.Припущення'!B25+'1.Припущення'!B26+'1.Припущення'!B27+'1.Припущення'!B28+'1.Припущення'!B29)+B32*'1.Припущення'!B30+C32*'1.Припущення'!B31 | E32: =C32-D32 | F32: =E32/C32 | G32: =E32/3.6/'1.Припущення'!B5
A33: 0.55 | B33: ='1.Припущення'!B7*A33 | C33: =B33*'1.Припущення'!B24 | D33: =('1.Припущення'!B25+'1.Припущення'!B26+'1.Припущення'!B27+'1.Припущення'!B28+'1.Припущення'!B29)+B33*'1.Припущення'!B30+C33*'1.Припущення'!B31 | E33: =C33-D33 | F33: =E33/C33 | G33: =E33/3.6/'1.Припущення'!B5
A34: 0.7 | B34: ='1.Припущення'!B7*A34 | C34: =B34*'1.Припущення'!B24 | D34: =('1.Припущення'!B25+'1.Припущення'!B26+'1.Припущення'!B27+'1.Припущення'!B28+'1.Припущення'!B29)+B34*'1.Припущення'!B30+C34*'1.Припущення'!B31 | E34: =C34-D34 | F34: =E34/C34 | G34: =E34/3.6/'1.Припущення'!B5
A35: 0.8 | B35: ='1.Припущення'!B7*A35 | C35: =B35*'1.Припущення'!B24 | D35: =('1.Припущення'!B25+'1.Припущення'!B26+'1.Припущення'!B27+'1.Припущення'!B28+'1.Припущення'!B29)+B35*'1.Припущення'!B30+C35*'1.Припущення'!B31 | E35: =C35-D35 | F35: =E35/C35 | G35: =E35/3.6/'1.Припущення'!B5
A38: C. IT-ІНЖЕНЕР — собівартість оплачуваної години
A39: Повна вартість інженера, $/рік | B39: ='1.Припущення'!B35*12*(1+'1.Припущення'!B36+'1.Припущення'!B38)+'1.Припущення'!B37*12
A40: Собівартість 1 оплачуваної години, $ | B40: =$B$39/'1.Припущення'!B8
A41: Ринок збуту (тільки внутрішній) | B41: Ставка $/год | C41: ВП $/год | D41: GM | E41: ВП на інженера $/рік
A42: Внутрішній UA, T&M, сеньйорна команда | B42: 26 | C42: =B42-$B$40 | D42: =C42/B42 | E42: =C42*'1.Припущення'!B8 | F42: збиткова модель
A43: Внутрішній UA, держ- і донорські проєкти | B43: 38 | C43: =B43-$B$40 | D43: =C43/B43 | E43: =C43*'1.Припущення'!B8 | F43: на межі нуля
A44: Експортні ставки вилучено з моделі на вимогу власника.
A46: D. ПІДПИСКИ — єдина модель, що дає маржу на внутрішньому ринку
A47: Модель | B47: LTV $ | C47: LTV / CAC | D47: CAC payback, міс | E47: Клієнтів до беззбитковості | F47: Вердикт
A48: D1 SaaS — мережі й інфраструктура | B48: ='1.Припущення'!B42*'1.Припущення'!C42/'1.Припущення'!E42 | C48: =B48/'1.Припущення'!D42 | D48: ='1.Припущення'!D42/('1.Припущення'!B42*'1.Припущення'!C42/12) | E48: =(8*$B$39+60000)/('1.Припущення'!B42*'1.Припущення'!C42) | F48: ІНВЕСТУВАТИ
...

Sheet 3.Ринки
A1: ВНУТРІШНІЙ РИНОК: TAM / SAM / SOM 2026-2029, млн грн (експорт вилучено)
A2: FTE — скільки людей потрібно, щоб узяти цей SOM у 2029. Темпи знижено після даних Держстату за січень-квітень 2026 (−2% р/р).
A4: Ринок | B4: TAM 2026 | C4: TAM 2027 | D4: TAM 2028 | E4: TAM 2029 | F4: SAM 2029 | G4: SOM 2026 | H4: SOM 2029 | I4: GM | J4: ВП 2029 | K4: FTE | L4: Драйвер / гальмо
A5: R4 ІТ-розробка для індустрій | B5: 3226 | C5: 3871 | D5: 4645 | E5: 5570 | F5: 1392 | G5: 17 | H5: 95 | I5: 0.58 | J5: =H5*I5 | K5: 28 | L5: двигун зростання; ядро — мережі. ROIC 957%
A6: R2 Інженерна геологія | B6: 2410 | C6: 2579 | D6: 2785 | E6: 2980 | F6: 894 | G6: 27 | H6: 74 | I6: 0.52 | J6: =H6*I6 | K6: 26 | L6: грошова корова: LTV/CAC 39, payback 0,9 міс
A7: R3 Лазерне сканування та BIM | B7: 400 | C7: 560 | D7: 784 | E7: 1058 | F7: 476 | G7: 0 | H7: 40 | I7: 0.55 | J7: =H7*I7 | K7: 20 | L7: НОВИЙ: CAGR 38% на регуляторному примусі (BIM у ДБН)
A8: R1 Топографія | B8: 2860 | C8: 3089 | D8: 3367 | E8: 3636 | F8: 1236 | G8: 20 | H8: 16 | I8: 0.26 | J8: =H8*I8 | K8: 15 | L8: канал, не зростання: $5 452 на людину, конкуренція макс.
A10: R4 ізсередини — вертикалі:
A11: Мережі й комунальна інфраструктура | B11: 950 | C11: 1159 | D11: 1437 | E11: 1753 | F11: 614 | G11: 0 | H11: 0 | I11: 0.62 | J11: =H11*I11 | K11: 0 | L11: ядро R4: найвищий GM, найнижча конкуренція, LTV/CAC 8,5
A12: Дороги й інфраструктура | B12: 650 | C12: 767 | D12: 959 | E12: 1189 | F12: 357 | G12: 0 | H12: 0 | I12: 0.52 | J12: =H12*I12 | K12: 0 | L12: донорські інфрапроєкти, прозорість
A13: Надра й карʼєри | B13: 380 | C13: 426 | D13: 481 | E13: 534 | F13: 240 | G13: 0 | H13: 0 | I13: 0.66 | J13: =H13*I13 | K13: 0 | L13: найвищий GM у R4, майже немає конкуренції
A14: Агро (GIS-ніша) | B14: 311 | C14: 361 | D14: 419 | E14: 486 | F14: 170 | G14: 0 | H14: 0 | I14: 0.6 | J14: =H14*I14 | K14: 0 | L14: НЕ ЙДЕМО: LTV/CAC 1,5, payback понад 30 міс
A15: Будівельники (ERP/BIM-процеси) | B15: 185 | C15: 222 | D15: 266 | E15: 320 | F15: 96 | G15: 0 | H15: 0 | I15: 0.45 | J15: =H15*I15 | K15: 0 | L15: TAM ВИПРАВЛЕНО: було 990, знизу вгору 185
A16: Громади | B16: 750 | C16: 825 | D16: 916 | E16: 1007 | F16: 252 | G16: 0 | H16: 0 | I16: 0.4 | J16: =H16*I16 | K16: 0 | L16: НЕ ЙДЕМО: демпінг, дрібні чеки, тендери
A17: РАЗОМ чотири ринки | B17: =SUM(B5:B8) | C17: =SUM(C5:C8) | D17: =SUM(D5:D8) | E17: =SUM(E5:E8) | F17: =SUM(F5:F8) | G17: =SUM(G5:G8) | H17: =SUM(H5:H8) | J17: =SUM(J5:J8) | K17: =SUM(K5:K8)
A19: Лазерне сканування та BIM (R3) — найшвидший ринок із чотирьох (CAGR 38%), якого сьогодні в компанії немає взагалі: 0 → 40 млн грн.
A20: TAM для будівельників виправлено: зверху вниз давало 990 млн, знизу вгору — 185 млн. Завищення в 5,4 раза.

Sheet 4.Матриця рішення
A1: МАТРИЦЯ РІШЕННЯ — чому ранжування за одним показником оманливе
A2: Оцінка 1-5. Ваги в рядку 5 редагуються.
A4: Ринок | B4: Масштаб (абс. ВП 2029) | C4: Якість економіки (ВП/FTE) | D4: Вартість захоплення (LTV/CAC) | E4: Право на перемогу | F4: Стійкість у сценарії C | G4: ЗВАЖЕНИЙ БАЛ | H4: Рішення | I4: Обґрунтування
A5: ВАГА | B5: 0.3 | C5: 0.25 | D5: 0.2 | E5: 0.15 | F5: 0.1
A6: M6 Мережі й комунальна інфра | B6: 5 | C6: 5 | D6: 4 | E6: 5 | F6: 3 | G6: =SUMPRODUCT(B6:F6,$B$5:$F$5) | H6: ★★★ ЯДРО | I6: єдиний рядок, де великий ВП/FTE поєднується з масштабом
A7: M5 Дорожники та інфраструктура | B7: 4 | C7: 4 | D7: 3 | E7: 4 | F7: 2 | G7: =SUMPRODUCT(B7:F7,$B$5:$F$5) | H7: ★★ ДВИГУН | I7: донорські гроші й вимога прозорості; ризик держзамовника
A8: M9 Надра/карʼєри: DaaS-обʼєми | B8: 2 | C8: 5 | D8: 5 | E8: 5 | F8: 4 | G8: =SUMPRODUCT(B8:F8,$B$5:$F$5) | H8: ★★ ДВИГУН | I8: LTV/CAC 13,3; та сама технологія, що й M5 — одна команда
A9: M1 Топогеодезичні вишукування | B9: 1 | C9: 1 | D9: 5 | E9: 5 | F9: 3 | G9: =SUMPRODUCT(B9:F9,$B$5:$F$5) | H9: ● ТІЛЬКИ КАНАЛ | I9: $4 222 на людину; цінність — у CAC підписки $1 800 замість $8 500
A10: M3 ІТ для будівельників | B10: 2 | C10: 3 | D10: 3 | E10: 3 | F10: 2 | G10: =SUMPRODUCT(B10:F10,$B$5:$F$5) | H10: ◐ опція | I10: SAM лише 337 млн грн
A11: M8 Розмінування: геодані + ІТ | B11: 1 | C11: 3 | D11: 4 | E11: 5 | F11: 1 | G11: =SUMPRODUCT(B11:F11,$B$5:$F$5) | H11: ◐ опція | I11: унікальний фіт, але фінансування політичне
A12: M4 ІТ / цифра для агро | B12: 2 | C12: 4 | D12: 1 | E12: 2 | F12: 4 | G12: =SUMPRODUCT(B12:F12,$B$5:$F$5) | H12: ✗ НІ | I12: LTV/CAC 1,8, payback 30,5 міс — ринок зайнятий
A13: M2 Інженерно-геологічні вишукування | B13: 5 | C13: 4 | D13: 5 | E13: 5 | F13: 3 | G13: =SUMPRODUCT(B13:F13,$B$5:$F$5) | H13: ★★★ ЯДРО | I13: ФАКТ 70 000 грн/день: GM 52%, окупність УРБ менш ніж рік
A14: M7 Громади / містобудівна докум. | B14: 1 | C14: 2 | D14: 2 | E14: 3 | F14: 2 | G14: =SUMPRODUCT(B14:F14,$B$5:$F$5) | H14: ✗ НІ | I14: тендери, демпінг, дрібні чеки

Sheet 5.P&L 2026-2029
A1: P&L: БАЗА 2026 → ЦІЛЬ 2029 (тільки внутрішній ринок)
A2: База 2026 — реконструкція за РИНКОВИМИ цінами і «легкою» структурою витрат, НЕ ваша звітність.
A4: БАЗА 2026 (~50 осіб) — перерахована за ринковими цінами
A5: Напрям | B5: FTE | C5: Виручка, млн грн | D5: GM % | E5: Валовий приб., млн | F5: ВП на 1 FTE, $ | G5: Коментар
A6: Геологія (3,3 бригади, util 55%) | B6: 12 | C6: 26.9 | D6: 0.44 | E6: =C6*D6 | F6: =IF(B6=0,0,E6*1000000/45.0/B6) | G6: ФАКТ 70 000 грн/день — увесь прибуток компанії
A7: Топогеодезія (9,2 бригади, util 62%) | B7: 22 | C7: 19.6 | D7: 0.21 | E7: =C7*D7 | F7: =IF(B7=0,0,E7*1000000/45.0/B7) | G7: 15 000 грн/день, «легка» структура витрат
A8: ІТ на внутрішній ринок | B8: 10 | C8: 17 | D8: 0.12 | E8: =C8*D8 | F8: =IF(B8=0,0,E8*1000000/45.0/B8) | G8: фікс-прайс; T&M за $26/год був би збитковим
A9: Адмін / продажі / бек-офіс | B9: 6 | C9: 0 | D9: 0 | E9: =C9*D9 | F9: =IF(B9=0,0,E9*1000000/45.0/B9)
A10: РАЗОМ | B10: =SUM(B6:B9) | C10: =SUM(C6:C9) | D10: =E10/C10 | E10: =SUM(E6:E9) | F10: =E10*1000000/45.0/B10
A11: SG&A, % від виручки | B11: 0.16 | C11: =C10*B11 | G11: для польової компанії 50 осіб типово 14-18%
A12: EBITDA, млн грн | C12: =E10-C11 | D12: =C12/C10 | E12: =C12*1000000/45.0 | F12: USD
A14: ЦІЛЬ 2029 (~100 осіб) — чотири ринки
A15: Напрям | B15: FTE | C15: Виручка, млн грн | D15: GM % | E15: Валовий приб., млн | F15: ВП на 1 FTE, $ | G15: Коментар
A16: R4 ІТ-розробка для індустрій (ядро — мережі) | B16: 28 | C16: 95.2 | D16: 0.58 | E16: =C16*D16 | F16: =IF(B16=0,0,E16*1000000/51.5/B16) | G16: СТАВКА 1: двигун зростання, ROIC 957%
A17: R2 Інженерна геологія (7 бригад, util 70%) | B17: 26 | C17: 74.4 | D17: 0.52 | E17: =C17*D17 | F17: =IF(B17=0,0,E17*1000000/51.5/B17) | G17: СТАВКА 3: грошова корова, фінансує R3 і R4
A18: R3 Лазерне сканування та BIM | B18: 20 | C18: 40 | D18: 0.55 | E18: =C18*D18 | F18: =IF(B18=0,0,E18*1000000/51.5/B18) | G18: СТАВКА 2: новий напрямок, CAGR 38%
A19: R1 Топографія (канал продажів) | B19: 15 | C19: 16.2 | D19: 0.26 | E19: =C19*D19 | F19: =IF(B19=0,0,E19*1000000/51.5/B19) | G19: не росте; дає доступ до 70 000 покупців
A20: Адмін / продажі / маркетинг / R&D | B20: 11 | C20: 0 | D20: 0 | E20: =C20*D20 | F20: =IF(B20=0,0,E20*1000000/51.5/B20)
A21: РАЗОМ | B21: =SUM(B16:B20) | C21: =SUM(C16:C20) | D21: =E21/C21 | E21: =SUM(E16:E20) | F21: =E21*1000000/51.5/B21
A22: SG&A, % від виручки | B22: 0.27 | C22: =C21*B22 | G22: вище, бо зʼявляються продажі й маркетинг продукту
A23: EBITDA, млн грн | C23: =E21-C22 | D23: =C23/C21 | E23: =C23*1000000/51.5 | F23: USD
A25: ДЕЛЬТА 2026 → 2029
A26: Виручка | B26: =C21/C10
A27: Валовий прибуток | B27: =E21/E10
A28: Валовий прибуток на 1 FTE | B28: =F21/F10
A29: EBITDA, млн грн | B29: =C12 | C29: → | D29: =C23

Sheet 6.Сценарії
A1: СЦЕНАРІЇ 2029 — ціна відмови від валютної виручки
A2: Без експорту всі чотири ринки живляться з одного джерела: бюджету й донорських грошей.
A4: Сценарій | B4: Ймовірність | C4: Коеф. внутр. ринків | D4: Виручка, млн грн | E4: EBITDA, млн грн | F4: Що це означає
A5: A. Війна триває, донори стабільні | B5: 0.55 | C5: 1 | D5: =(95.2+74.4+40+16.2)*C5 | E5: =(95.2*0.58+74.4*0.52+40*0.55+16.2*0.26)*C5-D5*0.27 | F5: базовий портфель
A6: B. Перемирʼя + донорський пакет | B6: 0.25 | C6: 1.85 | D6: =(95.2+74.4+40+16.2)*C6 | E6: =(95.2*0.58+74.4*0.52+40*0.55+16.2*0.26)*C6-D6*0.27 | F6: інфра, мережі й дороги стрибають
A7: C. Ескалація / зрив фінансування | B7: 0.2 | C7: 0.5 | D7: =(95.2+74.4+40+16.2)*C7 | E7: =(95.2*0.58+74.4*0.52+40*0.55+16.2*0.26)*C7-D7*0.27 | F7: виручка падає удвічі — нижню межу не тримає ніщо
A8: ОЧІКУВАНЕ ЗНАЧЕННЯ (зважене) | D8: =SUMPRODUCT(B5:B7,D5:D7) | E8: =SUMPRODUCT(B5:B7,E5:E7)
A10: Раніше експорт тримав нижню межу: внутрішні ринки падали на 45%, валютна лінія майже ні. Тепер такої лінії немає.

Sheet 7.Чотири ринки
A1: ЮНІТ-ЕКОНОМІКА ЧОТИРЬОХ РИНКІВ — ПОКУПЕЦЬ ЯК ЮНІТ
A2: Жовті комірки редагуються. LTV, LTV/CAC, payback, ROIC і бал рахуються формулами. Курс 51,5 грн/$.
A4: Ринок | B4: Юніт | C4: Чек, грн | D4: Повторів/рік | E4: Років життя | F4: GM | G4: CAC, грн | H4: Виручка/FTE, млн | I4: CapEx/FTE $ | J4: Конкур. 1-5 | K4: SAM 2029
A5: R1 Топографія | B5: обʼєкт / замовлення | C5: 25000 | D5: 1.4 | E5: 3 | F5: 0.26 | G5: 4000 | H5: 1.08 | I5: 9600 | J5: 5 | K5: 1236
A6: R2 Інженерна геологія | B6: обʼєкт / замовлення | C6: 250000 | D6: 1.2 | E6: 3 | F6: 0.52 | G6: 12000 | H6: 2.8615 | I6: 25000 | J6: 3 | K6: 894
A7: R3 Лазерне сканування та BIM | B7: обʼєкт / проєкт | C7: 400000 | D7: 1.3 | E7: 3 | F7: 0.55 | G7: 25000 | H7: 2 | I7: 9500 | J7: 3 | K7: 476
A8: R4 ІТ-розробка для індустрій | B8: клієнт / підписка | C8: 721000 | D8: 1 | E8: 6 | F8: 0.58 | G8: 300000 | H8: 3.4 | I8: 4000 | J8: 3 | K8: 1392
A10: РОЗРАХУНОК
A11: Ринок | B11: LTV $ | C11: CAC $ | D11: LTV / CAC | E11: Payback, міс | F11: ВП/FTE $ | G11: ROIC | H11: ВП на SAM, млн
A12: =A5 | B12: =C5*D5*E5*F5/51.5 | C12: =G5/51.5 | D12: =B12/C12 | E12: =C12/(C5*D5*F5/12/51.5) | F12: =H5*F5*1000000/51.5 | G12: =F12/I5 | H12: =K5*F5
A13: =A6 | B13: =C6*D6*E6*F6/51.5 | C13: =G6/51.5 | D13: =B13/C13 | E13: =C13/(C6*D6*F6/12/51.5) | F13: =H6*F6*1000000/51.5 | G13: =F13/I6 | H13: =K6*F6
A14: =A7 | B14: =C7*D7*E7*F7/51.5 | C14: =G7/51.5 | D14: =B14/C14 | E14: =C14/(C7*D7*F7/12/51.5) | F14: =H7*F7*1000000/51.5 | G14: =F14/I7 | H14: =K7*F7
A15: =A8 | B15: =C8*D8*E8*F8/51.5 | C15: =G8/51.5 | D15: =B15/C15 | E15: =C15/(C8*D8*F8/12/51.5) | F15: =H8*F8*1000000/51.5 | G15: =F15/I8 | H15: =K8*F8
A16: Поріг інвестора: LTV/CAC > 3 і payback < 12 міс. Усі чотири ринки проходять.
A18: ПЕРЕВІРКА ОБСЯГУ РИНКУ: ДВІ НЕЗАЛЕЖНІ ОЦІНКИ
A19: Ринок | B19: Зверху вниз | C19: Покупців | D19: × річний чек | E19: Знизу вгору | F19: Розбіжність | G19: Вердикт
A20: R1 Топографія | B20: 2860 | C20: 70000 | D20: 40000 | E20: =C20*D20/1000000 | F20: =E20/B20-1 | G20: =IF(ABS(F20)<0.35,"✓ підтверджено","⚠ ЦИФРІ НЕ ДОВІРЯТИ")
A21: R2 Інженерна геологія | B21: 2410 | C21: 12000 | D21: 200000 | E21: =C21*D21/1000000 | F21: =E21/B21-1 | G21: =IF(ABS(F21)<0.35,"✓ підтверджено","⚠ ЦИФРІ НЕ ДОВІРЯТИ")
A22: R3 Лазерне сканування та BIM | B22: 428 | C22: 1030 | D22: 350000 | E22: =C22*D22/1000000 | F22: =E22/B22-1 | G22: =IF(ABS(F22)<0.35,"✓ підтверджено","⚠ ЦИФРІ НЕ ДОВІРЯТИ")
A23: R4.5 Будівельники (в складі R4) | B23: 990 | C23: 410 | D23: 450000 | E23: =C23*D23/1000000 | F23: =E23/B23-1 | G23: =IF(ABS(F23)<0.35,"✓ підтверджено","⚠ ЦИФРІ НЕ ДОВІРЯТИ")
A25: Розбіжність до ±35% — норма. Більше — оцінка зроблена лише одним методом і не перевірена.
